Workbook

Sheet PAINEL
A1: PAINEL FINANCEIRO E DE OCUPAÇÃO
A3: Ano | B3: 2026 | M3: A receber (R$) | N3: =SUMIFS(RESERVAS!$U$6:$U$203,RESERVAS!$I$6:$I$203,"<>Cancelada",RESERVAS!$I$6:$I$203,"<>Consulta") -> 48093.62
A5: Receita bruta (R$) | B5: =SUM(F13:F24) -> 28541.67 | D5: Custos diretos (R$) | E5: =SUM(G13:G24) -> 32.05 | G5: Despesas gerais (R$) | H5: =SUM(H13:H24) -> 0 | J5: Lucro final (R$) | K5: =SUM(I13:I24) -> 28509.62
A8: Diárias alugadas | B8: =SUM(C13:C24) -> 53 | D8: Dias disponíveis | E8: =SUM(D13:D24) -> 677 | G8: Ocupação anual | H8: =IF(SUM(B13:B24)=0,0,SUM(C13:C24)/SUM(B13:B24)) -> 0.07260274 | J8: Diária média (R$) | K8: =IF(B8=0,0,B5/B8) -> 538.52208
A12: Mês | B12: Dias | C12: Alugadas | D12: Disponíveis | E12: Ocupação | F12: Receita (R$) | G12: Custos diretos (R$) | H12: Despesas gerais (R$) | I12: Lucro final (R$) | J12: Margem | L12: EXEMPLO CADASTRADO
A13: Janeiro | B13: =DAY(EOMONTH(DATE($B$3,1,1),0))*2 -> 62 | C13: =SUMPRODUCT((RESERVAS!$C$6:$C$203<DATE($B$3,2,1))*(RESERVAS!$D$6:$D$203>DATE($B$3,1,1))*(RESERVAS!$I$6:$I$203<>"Cancelada")*(RESERVAS!$I$6:$I$203<>"Consulta")*(((RESERVAS!$D$6:$D$203<DATE($B$3,2,1))*RESERVAS!$D$6:$D$203+(RESERVAS!$D$6:$D$203>=DATE($B$3,2,1))*DATE($B$3,2,1))-((RESERVAS!$C$6:$C$203>DATE($B$3,1,1))*RESERVAS!$C$6:$C$203+(RESERVAS!$C$6:$C$203<=DATE($B$3,1,1))*DATE($B$3,1,1)))) -> 0 | D13: =MAX(0,B13-C13) -> 62 | E13: =IF(B13=0,0,C13/B13) -> 0 | F13: =SUMPRODUCT((RESERVAS!$C$6:$C$203<DATE($B$3,2,1))*(RESERVAS!$D$6:$D$203>DATE($B$3,1,1))*(RESERVAS!$I$6:$I$203<>"Cancelada")*(RESERVAS!$I$6:$I$203<>"Consulta")*RESERVAS!$F$6:$F$203*(((RESERVAS!$D$6:$D$203<DATE($B$3,2,1))*RESERVAS!$D$6:$D$203+(RESERVAS!$D$6:$D$203>=DATE($B$3,2,1))*DATE($B$3,2,1))-((RESERVAS!$C$6:$C$203>DATE($B$3,1,1))*RESERVAS!$C$6:$C$203+(RESERVAS!$C$6:$C$203<=DATE($B$3,1,1))*DATE($B$3,1,1)))) -> 0 | G13: =SUMPRODUCT((RESERVAS!$C$6:$C$203<DATE($B$3,2,1))*(RESERVAS!$D$6:$D$203>DATE($B$3,1,1))*(RESERVAS!$I$6:$I$203<>"Cancelada")*(RESERVAS!$I$6:$I$203<>"Consulta")*RESERVAS!$T$6:$T$203*(((RESERVAS!$D$6:$D$203<DATE($B$3,2,1))*RESERVAS!$D$6:$D$203+(RESERVAS!$D$6:$D$203>=DATE($B$3,2,1))*DATE($B$3,2,1))-((RESERVAS!$C$6:$C$203>DATE($B$3,1,1))*RESERVAS!$C$6:$C$203+(RESERVAS!$C$6:$C$203<=DATE($B$3,1,1))*DATE($B$3,1,1)))) -> 0 | H13: =SUMIFS('DESPESAS CASA'!$D$6:$D$305,'DESPESAS CASA'!$A$6:$A$305,">="&DATE($B$3,1,1),'DESPESAS CASA'!$A$6:$A$305,"<"&DATE($B$3,2,1),'DESPESAS CASA'!$E$6:$E$305,"") -> 0 | I13: =F13-G13-H13 -> 0 | J13: =IF(F13=0,0,I13/F13) -> 0 | L13: Período | M13: 25/12/2026 a 04/01/2027
A14: Fevereiro | B14: =DAY(EOMONTH(DATE($B$3,2,1),0))*2 -> 56 | C14: =SUMPRODUCT((RESERVAS!$C$6:$C$203<DATE($B$3,3,1))*(RESERVAS!$D$6:$D$203>DATE($B$3,2,1))*(RESERVAS!$I$6:$I$203<>"Cancelada")*(RESERVAS!$I$6:$I$203<>"Consulta")*(((RESERVAS!$D$6:$D$203<DATE($B$3,3,1))*RESERVAS!$D$6:$D$203+(RESERVAS!$D$6:$D$203>=DATE($B$3,3,1))*DATE($B$3,3,1))-((RESERVAS!$C$6:$C$203>DATE($B$3,2,1))*RESERVAS!$C$6:$C$203+(RESERVAS!$C$6:$C$203<=DATE($B$3,2,1))*DATE($B$3,2,1)))) -> 0 | D14: =MAX(0,B14-C14) -> 56 | E14: =IF(B14=0,0,C14/B14) -> 0 | F14: =SUMPRODUCT((RESERVAS!$C$6:$C$203<DATE($B$3,3,1))*(RESERVAS!$D$6:$D$203>DATE($B$3,2,1))*(RESERVAS!$I$6:$I$203<>"Cancelada")*(RESERVAS!$I$6:$I$203<>"Consulta")*RESERVAS!$F$6:$F$203*(((RESERVAS!$D$6:$D$203<DATE($B$3,3,1))*RESERVAS!$D$6:$D$203+(RESERVAS!$D$6:$D$203>=DATE($B$3,3,1))*DATE($B$3,3,1))-((RESERVAS!$C$6:$C$203>DATE($B$3,2,1))*RESERVAS!$C$6:$C$203+(RESERVAS!$C$6:$C$203<=DATE($B$3,2,1))*DATE($B$3,2,1)))) -> 0 | G14: =SUMPRODUCT((RESERVAS!$C$6:$C$203<DATE($B$3,3,1))*(RESERVAS!$D$6:$D$203>DATE($B$3,2,1))*(RESERVAS!$I$6:$I$203<>"Cancelada")*(RESERVAS!$I$6:$I$203<>"Consulta")*RESERVAS!$T$6:$T$203*(((RESERVAS!$D$6:$D$203<DATE($B$3,3,1))*RESERVAS!$D$6:$D$203+(RESERVAS!$D$6:$D$203>=DATE($B$3,3,1))*DATE($B$3,3,1))-((RESERVAS!$C$6:$C$203>DATE($B$3,2,1))*RESERVAS!$C$6:$C$203+(RESERVAS!$C$6:$C$203<=DATE($B$3,2,1))*DATE($B$3,2,1)))) -> 0 | H14: =SUMIFS('DESPESAS CASA'!$D$6:$D$305,'DESPESAS CASA'!$A$6:$A$305,">="&DATE($B$3,2,1),'DESPESAS CASA'!$A$6:$A$305,"<"&DATE($B$3,3,1),'DESPESAS CASA'!$E$6:$E$305,"") -> 0 | I14: =F14-G14-H14 -> 0 | J14: =IF(F14=0,0,I14/F14) -> 0 | L14: Diárias | M14: 10
A15: Março | B15: =DAY(EOMONTH(DATE($B$3,3,1),0))*2 -> 62 | C15: =SUMPRODUCT((RESERVAS!$C$6:$C$203<DATE($B$3,4,1))*(RESERVAS!$D$6:$D$203>DATE($B$3,3,1))*(RESERVAS!$I$6:$I$203<>"Cancelada")*(RESERVAS!$I$6:$I$203<>"Consulta")*(((RESERVAS!$D$6:$D$203<DATE($B$3,4,1))*RESERVAS!$D$6:$D$203+(RESERVAS!$D$6:$D$203>=DATE($B$3,4,1))*DATE($B$3,4,1))-((RESERVAS!$C$6:$C$203>DATE($B$3,3,1))*RESERVAS!$C$6:$C$203+(RESERVAS!$C$6:$C$203<=DATE($B$3,3,1))*DATE($B$3,3,1)))) -> 0 | D15: =MAX(0,B15-C15) -> 62 | E15: =IF(B15=0,0,C15/B15) -> 0 | F15: =SUMPRODUCT((RESERVAS!$C$6:$C$203<DATE($B$3,4,1))*(RESERVAS!$D$6:$D$203>DATE($B$3,3,1))*(RESERVAS!$I$6:$I$203<>"Cancelada")*(RESERVAS!$I$6:$I$203<>"Consulta")*RESERVAS!$F$6:$F$203*(((RESERVAS!$D$6:$D$203<DATE($B$3,4,1))*RESERVAS!$D$6:$D$203+(RESERVAS!$D$6:$D$203>=DATE($B$3,4,1))*DATE($B$3,4,1))-((RESERVAS!$C$6:$C$203>DATE($B$3,3,1))*RESERVAS!$C$6:$C$203+(RESERVAS!$C$6:$C$203<=DATE($B$3,3,1))*DATE($B$3,3,1)))) -> 0 | G15: =SUMPRODUCT((RESERVAS!$C$6:$C$203<DATE($B$3,4,1))*(RESERVAS!$D$6:$D$203>DATE($B$3,3,1))*(RESERVAS!$I$6:$I$203<>"Cancelada")*(RESERVAS!$I$6:$I$203<>"Consulta")*RESERVAS!$T$6:$T$203*(((RESERVAS!$D$6:$D$203<DATE($B$3,4,1))*RESERVAS!$D$6:$D$203+(RESERVAS!$D$6:$D$203>=DATE($B$3,4,1))*DATE($B$3,4,1))-((RESERVAS!$C$6:$C$203>DATE($B$3,3,1))*RESERVAS!$C$6:$C$203+(RESERVAS!$C$6:$C$203<=DATE($B$3,3,1))*DATE($B$3,3,1)))) -> 0 | H15: =SUMIFS('DESPESAS CASA'!$D$6:$D$305,'DESPESAS CASA'!$A$6:$A$305,">="&DATE($B$3,3,1),'DESPESAS CASA'!$A$6:$A$305,"<"&DATE($B$3,4,1),'DESPESAS CASA'!$E$6:$E$305,"") -> 0 | I15: =F15-G15-H15 -> 0 | J15: =IF(F15=0,0,I15/F15) -> 0 | L15: Valor diária | M15: 1100
A16: Abril | B16: =DAY(EOMONTH(DATE($B$3,4,1),0))*2 -> 60 | C16: =SUMPRODUCT((RESERVAS!$C$6:$C$203<DATE($B$3,5,1))*(RESERVAS!$D$6:$D$203>DATE($B$3,4,1))*(RESERVAS!$I$6:$I$203<>"Cancelada")*(RESERVAS!$I$6:$I$203<>"Consulta")*(((RESERVAS!$D$6:$D$203<DATE($B$3,5,1))*RESERVAS!$D$6:$D$203+(RESERVAS!$D$6:$D$203>=DATE($B$3,5,1))*DATE($B$3,5,1))-((RESERVAS!$C$6:$C$203>DATE($B$3,4,1))*RESERVAS!$C$6:$C$203+(RESERVAS!$C$6:$C$203<=DATE($B$3,4,1))*DATE($B$3,4,1)))) -> 0 | D16: =MAX(0,B16-C16) -> 60 | E16: =IF(B16=0,0,C16/B16) -> 0 | F16: =SUMPRODUCT((RESERVAS!$C$6:$C$203<DATE($B$3,5,1))*(RESERVAS!$D$6:$D$203>DATE($B$3,4,1))*(RESERVAS!$I$6:$I$203<>"Cancelada")*(RESERVAS!$I$6:$I$203<>"Consulta")*RESERVAS!$F$6:$F$203*(((RESERVAS!$D$6:$D$203<DATE($B$3,5,1))*RESERVAS!$D$6:$D$203+(RESERVAS!$D$6:$D$203>=DATE($B$3,5,1))*DATE($B$3,5,1))-((RESERVAS!$C$6:$C$203>DATE($B$3,4,1))*RESERVAS!$C$6:$C$203+(RESERVAS!$C$6:$C$203<=DATE($B$3,4,1))*DATE($B$3,4,1)))) -> 0 | G16: =SUMPRODUCT((RESERVAS!$C$6:$C$203<DATE($B$3,5,1))*(RESERVAS!$D$6:$D$203>DATE($B$3,4,1))*(RESERVAS!$I$6:$I$203<>"Cancelada")*(RESERVAS!$I$6:$I$203<>"Consulta")*RESERVAS!$T$6:$T$203*(((RESERVAS!$D$6:$D$203<DATE($B$3,5,1))*RESERVAS!$D$6:$D$203+(RESERVAS!$D$6:$D$203>=DATE($B$3,5,1))*DATE($B$3,5,1))-((RESERVAS!$C$6:$C$203>DATE($B$3,4,1))*RESERVAS!$C$6:$C$203+(RESERVAS!$C$6:$C$203<=DATE($B$3,4,1))*DATE($B$3,4,1)))) -> 0 | H16: =SUMIFS('DESPESAS CASA'!$D$6:$D$305,'DESPESAS CASA'!$A$6:$A$305,">="&DATE($B$3,4,1),'DESPESAS CASA'!$A$6:$A$305,"<"&DATE($B$3,5,1),'DESPESAS CASA'!$E$6:$E$305,"") -> 0 | I16: =F16-G16-H16 -> 0 | J16: =IF(F16=0,0,I16/F16) -> 0 | L16: Receita total | M16: 11000
A17: Maio | B17: =DAY(EOMONTH(DATE($B$3,5,1),0))*2 -> 62 | C17: =SUMPRODUCT((RESERVAS!$C$6:$C$203<DATE($B$3,6,1))*(RESERVAS!$D$6:$D$203>DATE($B$3,5,1))*(RESERVAS!$I$6:$I$203<>"Cancelada")*(RESERVAS!$I$6:$I$203<>"Consulta")*(((RESERVAS!$D$6:$D$203<DATE($B$3,6,1))*RESERVAS!$D$6:$D$203+(RESERVAS!$D$6:$D$203>=DATE($B$3,6,1))*DATE($B$3,6,1))-((RESERVAS!$C$6:$C$203>DATE($B$3,5,1))*RESERVAS!$C$6:$C$203+(RESERVAS!$C$6:$C$203<=DATE($B$3,5,1))*DATE($B$3,5,1)))) -> 0 | D17: =MAX(0,B17-C17) -> 62 | E17: =IF(B17=0,0,C17/B17) -> 0 | F17: =SUMPRODUCT((RESERVAS!$C$6:$C$203<DATE($B$3,6,1))*(RESERVAS!$D$6:$D$203>DATE($B$3,5,1))*(RESERVAS!$I$6:$I$203<>"Cancelada")*(RESERVAS!$I$6:$I$203<>"Consulta")*RESERVAS!$F$6:$F$203*(((RESERVAS!$D$6:$D$203<DATE($B$3,6,1))*RESERVAS!$D$6:$D$203+(RESERVAS!$D$6:$D$203>=DATE($B$3,6,1))*DATE($B$3,6,1))-((RESERVAS!$C$6:$C$203>DATE($B$3,5,1))*RESERVAS!$C$6:$C$203+(RESERVAS!$C$6:$C$203<=DATE($B$3,5,1))*DATE($B$3,5,1)))) -> 0 | G17: =SUMPRODUCT((RESERVAS!$C$6:$C$203<DATE($B$3,6,1))*(RESERVAS!$D$6:$D$203>DATE($B$3,5,1))*(RESERVAS!$I$6:$I$203<>"Cancelada")*(RESERVAS!$I$6:$I$203<>"Consulta")*RESERVAS!$T$6:$T$203*(((RESERVAS!$D$6:$D$203<DATE($B$3,6,1))*RESERVAS!$D$6:$D$203+(RESERVAS!$D$6:$D$203>=DATE($B$3,6,1))*DATE($B$3,6,1))-((RESERVAS!$C$6:$C$203>DATE($B$3,5,1))*RESERVAS!$C$6:$C$203+(RESERVAS!$C$6:$C$203<=DATE($B$3,5,1))*DATE($B$3,5,1)))) -> 0 | H17: =SUMIFS('DESPESAS CASA'!$D$6:$D$305,'DESPESAS CASA'!$A$6:$A$305,">="&DATE($B$3,5,1),'DESPESAS CASA'!$A$6:$A$305,"<"&DATE($B$3,6,1),'DESPESAS CASA'!$E$6:$E$305,"") -> 0 | I17: =F17-G17-H17 -> 0 | J17: =IF(F17=0,0,I17/F17) -> 0 | L17: Rateio | M17: Dez/26: R$ 7.700 | Jan/27: R$ 3.300
A18: Junho | B18: =DAY(EOMONTH(DATE($B$3,6,1),0))*2 -> 60 | C18: =SUMPRODUCT((RESERVAS!$C$6:$C$203<DATE($B$3,7,1))*(RESERVAS!$D$6:$D$203>DATE($B$3,6,1))*(RESERVAS!$I$6:$I$203<>"Cancelada")*(RESERVAS!$I$6:$I$203<>"Consulta")*(((RESERVAS!$D$6:$D$203<DATE($B$3,7,1))*RESERVAS!$D$6:$D$203+(RESERVAS!$D$6:$D$203>=DATE($B$3,7,1))*DATE($B$3,7,1))-((RESERVAS!$C$6:$C$203>DATE($B$3,6,1))*RESERVAS!$C$6:$C$203+(RESERVAS!$C$6:$C$203<=DATE($B$3,6,1))*DATE($B$3,6,1)))) -> 0 | D18: =MAX(0,B18-C18) -> 60 | E18: =IF(B18=0,0,C18/B18) -> 0 | F18: =SUMPRODUCT((RESERVAS!$C$6:$C$203<DATE($B$3,7,1))*(RESERVAS!$D$6:$D$203>DATE($B$3,6,1))*(RESERVAS!$I$6:$I$203<>"Cancelada")*(RESERVAS!$I$6:$I$203<>"Consulta")*RESERVAS!$F$6:$F$203*(((RESERVAS!$D$6:$D$203<DATE($B$3,7,1))*RESERVAS!$D$6:$D$203+(RESERVAS!$D$6:$D$203>=DATE($B$3,7,1))*DATE($B$3,7,1))-((RESERVAS!$C$6:$C$203>DATE($B$3,6,1))*RESERVAS!$C$6:$C$203+(RESERVAS!$C$6:$C$203<=DATE($B$3,6,1))*DATE($B$3,6,1)))) -> 0 | G18: =SUMPRODUCT((RESERVAS!$C$6:$C$203<DATE($B$3,7,1))*(RESERVAS!$D$6:$D$203>DATE($B$3,6,1))*(RESERVAS!$I$6:$I$203<>"Cancelada")*(RESERVAS!$I$6:$I$203<>"Consulta")*RESERVAS!$T$6:$T$203*(((RESERVAS!$D$6:$D$203<DATE($B$3,7,1))*RESERVAS!$D$6:$D$203+(RESERVAS!$D$6:$D$203>=DATE($B$3,7,1))*DATE($B$3,7,1))-((RESERVAS!$C$6:$C$203>DATE($B$3,6,1))*RESERVAS!$C$6:$C$203+(RESERVAS!$C$6:$C$203<=DATE($B$3,6,1))*DATE($B$3,6,1)))) -> 0 | H18: =SUMIFS('DESPESAS CASA'!$D$6:$D$305,'DESPESAS CASA'!$A$6:$A$305,">="&DATE($B$3,6,1),'DESPESAS CASA'!$A$6:$A$305,"<"&DATE($B$3,7,1),'DESPESAS CASA'!$E$6:$E$305,"") -> 0 | I18: =F18-G18-H18 -> 0 | J18: =IF(F18=0,0,I18/F18) -> 0
A19: Julho | B19: =DAY(EOMONTH(DATE($B$3,7,1),0))*2 -> 62 | C19: =SUMPRODUCT((RESERVAS!$C$6:$C$203<DATE($B$3,8,1))*(RESERVAS!$D$6:$D$203>DATE($B$3,7,1))*(RESERVAS!$I$6:$I$203<>"Cancelada")*(RESERVAS!$I$6:$I$203<>"Consulta")*(((RESERVAS!$D$6:$D$203<DATE($B$3,8,1))*RESERVAS!$D$6:$D$203+(RESERVAS!$D$6:$D$203>=DATE($B$3,8,1))*DATE($B$3,8,1))-((RESERVAS!$C$6:$C$203>DATE($B$3,7,1))*RESERVAS!$C$6:$C$203+(RESERVAS!$C$6:$C$203<=DATE($B$3,7,1))*DATE($B$3,7,1)))) -> 0 | D19: =MAX(0,B19-C19) -> 62 | E19: =IF(B19=0,0,C19/B19) -> 0 | F19: =SUMPRODUCT((RESERVAS!$C$6:$C$203<DATE($B$3,8,1))*(RESERVAS!$D$6:$D$203>DATE($B$3,7,1))*(RESERVAS!$I$6:$I$203<>"Cancelada")*(RESERVAS!$I$6:$I$203<>"Consulta")*RESERVAS!$F$6:$F$203*(((RESERVAS!$D$6:$D$203<DATE($B$3,8,1))*RESERVAS!$D$6:$D$203+(RESERVAS!$D$6:$D$203>=DATE($B$3,8,1))*DATE($B$3,8,1))-((RESERVAS!$C$6:$C$203>DATE($B$3,7,1))*RESERVAS!$C$6:$C$203+(RESERVAS!$C$6:$C$203<=DATE($B$3,7,1))*DATE($B$3,7,1)))) -> 0 | G19: =SUMPRODUCT((RESERVAS!$C$6:$C$203<DATE($B$3,8,1))*(RESERVAS!$D$6:$D$203>DATE($B$3,7,1))*(RESERVAS!$I$6:$I$203<>"Cancelada")*(RESERVAS!$I$6:$I$203<>"Consulta")*RESERVAS!$T$6:$T$203*(((RESERVAS!$D$6:$D$203<DATE($B$3,8,1))*RESERVAS!$D$6:$D$203+(RESERVAS!$D$6:$D$203>=DATE($B$3,8,1))*DATE($B$3,8,1))-((RESERVAS!$C$6:$C$203>DATE($B$3,7,1))*RESERVAS!$C$6:$C$203+(RESERVAS!$C$6:$C$203<=DATE($B$3,7,1))*DATE($B$3,7,1)))) -> 0 | H19: =SUMIFS('DESPESAS CASA'!$D$6:$D$305,'DESPESAS CASA'!$A$6:$A$305,">="&DATE($B$3,7,1),'DESPESAS CASA'!$A$6:$A$305,"<"&DATE($B$3,8,1),'DESPESAS CASA'!$E$6:$E$305,"") -> 0 | I19: =F19-G19-H19 -> 0 | J19: =IF(F19=0,0,I19/F19) -> 0
A20: Agosto | B20: =DAY(EOMONTH(DATE($B$3,8,1),0))*2 -> 62 | C20: =SUMPRODUCT((RESERVAS!$C$6:$C$203<DATE($B$3,9,1))*(RESERVAS!$D$6:$D$203>DATE($B$3,8,1))*(RESERVAS!$I$6:$I$203<>"Cancelada")*(RESERVAS!$I$6:$I$203<>"Consulta")*(((RESERVAS!$D$6:$D$203<DATE($B$3,9,1))*RESERVAS!$D$6:$D$203+(RESERVAS!$D$6:$D$203>=DATE($B$3,9,1))*DATE($B$3,9,1))-((RESERVAS!$C$6:$C$203>DATE($B$3,8,1))*RESERVAS!$C$6:$C$203+(RESERVAS!$C$6:$C$203<=DATE($B$3,8,1))*DATE($B$3,8,1)))) -> 0 | D20: =MAX(0,B20-C20) -> 62 | E20: =IF(B20=0,0,C20/B20) -> 0 | F20: =SUMPRODUCT((RESERVAS!$C$6:$C$203<DATE($B$3,9,1))*(RESERVAS!$D$6:$D$203>DATE($B$3,8,1))*(RESERVAS!$I$6:$I$203<>"Cancelada")*(RESERVAS!$I$6:$I$203<>"Consulta")*RESERVAS!$F$6:$F$203*(((RESERVAS!$D$6:$D$203<DATE($B$3,9,1))*RESERVAS!$D$6:$D$203+(RESERVAS!$D$6:$D$203>=DATE($B$3,9,1))*DATE($B$3,9,1))-((RESERVAS!$C$6:$C$203>DATE($B$3,8,1))*RESERVAS!$C$6:$C$203+(RESERVAS!$C$6:$C$203<=DATE($B$3,8,1))*DATE($B$3,8,1)))) -> 0 | G20: =SUMPRODUCT((RESERVAS!$C$6:$C$203<DATE($B$3,9,1))*(RESERVAS!$D$6:$D$203>DATE($B$3,8,1))*(RESERVAS!$I$6:$I$203<>"Cancelada")*(RESERVAS!$I$6:$I$203<>"Consulta")*RESERVAS!$T$6:$T$203*(((RESERVAS!$D$6:$D$203<DATE($B$3,9,1))*RESERVAS!$D$6:$D$203+(RESERVAS!$D$6:$D$203>=DATE($B$3,9,1))*DATE($B$3,9,1))-((RESERVAS!$C$6:$C$203>DATE($B$3,8,1))*RESERVAS!$C$6:$C$203+(RESERVAS!$C$6:$C$203<=DATE($B$3,8,1))*DATE($B$3,8,1)))) -> 0 | H20: =SUMIFS('DESPESAS CASA'!$D$6:$D$305,'DESPESAS CASA'!$A$6:$A$305,">="&DATE($B$3,8,1),'DESPESAS CASA'!$A$6:$A$305,"<"&DATE($B$3,9,1),'DESPESAS CASA'!$E$6:$E$305,"") -> 0 | I20: =F20-G20-H20 -> 0 | J20: =IF(F20=0,0,I20/F20) -> 0
A21: Setembro | B21: =DAY(EOMONTH(DATE($B$3,9,1),0))*2 -> 60 | C21: =SUMPRODUCT((RESERVAS!$C$6:$C$203<DATE($B$3,10,1))*(RESERVAS!$D$6:$D$203>DATE($B$3,9,1))*(RESERVAS!$I$6:$I$203<>"Cancelada")*(RESERVAS!$I$6:$I$203<>"Consulta")*(((RESERVAS!$D$6:$D$203<DATE($B$3,10,1))*RESERVAS!$D$6:$D$203+(RESERVAS!$D$6:$D$203>=DATE($B$3,10,1))*DATE($B$3,10,1))-((RESERVAS!$C$6:$C$203>DATE($B$3,9,1))*RESERVAS!$C$6:$C$203+(RESERVAS!$C$6:$C$203<=DATE($B$3,9,1))*DATE($B$3,9,1)))) -> 8 | D21: =MAX(0,B21-C21) -> 52 | E21: =IF(B21=0,0,C21/B21) -> 0.13333333 | F21: =SUMPRODUCT((RESERVAS!$C$6:$C$203<DATE($B$3,10,1))*(RESERVAS!$D$6:$D$203>DATE($B$3,9,1))*(RESERVAS!$I$6:$I$203<>"Cancelada")*(RESERVAS!$I$6:$I$203<>"Consulta")*RESERVAS!$F$6:$F$203*(((RESERVAS!$D$6:$D$203<DATE($B$3,10,1))*RESERVAS!$D$6:$D$203+(RESERVAS!$D$6:$D$203>=DATE($B$3,10,1))*DATE($B$3,10,1))-((RESERVAS!$C$6:$C$203>DATE($B$3,9,1))*RESERVAS!$C$6:$C$203+(RESERVAS!$C$6:$C$203<=DATE($B$3,9,1))*DATE($B$3,9,1)))) -> 2800 | G21: =SUMPRODUCT((RESERVAS!$C$6:$C$203<DATE($B$3,10,1))*(RESERVAS!$D$6:$D$203>DATE($B$3,9,1))*(RESERVAS!$I$6:$I$203<>"Cancelada")*(RESERVAS!$I$6:$I$203<>"Consulta")*RESERVAS!$T$6:$T$203*(((RESERVAS!$D$6:$D$203<DATE($B$3,10,1))*RESERVAS!$D$6:$D$203+(RESERVAS!$D$6:$D$203>=DATE($B$3,10,1))*DATE($B$3,10,1))-((RESERVAS!$C$6:$C$203>DATE($B$3,9,1))*RESERVAS!$C$6:$C$203+(RESERVAS!$C$6:$C$203<=DATE($B$3,9,1))*DATE($B$3,9,1)))) -> 32.05 | H21: =SUMIFS('DESPESAS CASA'!$D$6:$D$305,'DESPESAS CASA'!$A$6:$A$305,">="&DATE($B$3,9,1),'DESPESAS CASA'!$A$6:$A$305,"<"&DATE($B$3,10,1),'DESPESAS CASA'!$E$6:$E$305,"") -> 0 | I21: =F21-G21-H21 -> 2767.95 | J21: =IF(F21=0,0,I21/F21) -> 0.98855357
A22: Outubro | B22: =DAY(EOMONTH(DATE($B$3,10,1),0))*2 -> 62 | C22: =SUMPRODUCT((RESERVAS!$C$6:$C$203<DATE($B$3,11,1))*(RESERVAS!$D$6:$D$203>DATE($B$3,10,1))*(RESERVAS!$I$6:$I$203<>"Cancelada")*(RESERVAS!$I$6:$I$203<>"Consulta")*(((RESERVAS!$D$6:$D$203<DATE($B$3,11,1))*RESERVAS!$D$6:$D$203+(RESERVAS!$D$6:$D$203>=DATE($B$3,11,1))*DATE($B$3,11,1))-((RESERVAS!$C$6:$C$203>DATE($B$3,10,1))*RESERVAS!$C$6:$C$203+(RESERVAS!$C$6:$C$203<=DATE($B$3,10,1))*DATE($B$3,10,1)))) -> 12 | D22: =MAX(0,B22-C22) -> 50 | E22: =IF(B22=0,0,C22/B22) -> 0.19354839 | F22: =SUMPRODUCT((RESERVAS!$C$6:$C$203<DATE($B$3,11,1))*(RESERVAS!$D$6:$D$203>DATE($B$3,10,1))*(RESERVAS!$I$6:$I$203<>"Cancelada")*(RESERVAS!$I$6:$I$203<>"Consulta")*RESERVAS!$F$6:$F$203*(((RESERVAS!$D$6:$D$203<DATE($B$3,11,1))*RESERVAS!$D$6:$D$203+(RESERVAS!$D$6:$D$203>=DATE($B$3,11,1))*DATE($B$3,11,1))-((RESERVAS!$C$6:$C$203>DATE($B$3,10,1))*RESERVAS!$C$6:$C$203+(RESERVAS!$C$6:$C$203<=DATE($B$3,10,1))*DATE($B$3,10,1)))) -> 4909.675 | G22: =SUMPRODUCT((RESERVAS!$C$6:$C$203<DATE($B$3,11,1))*(RESERVAS!$D$6:$D$203>DATE($B$3,10,1))*(RESERVAS!$I$6:$I$203<>"Cancelada")*(RESERVAS!$I$6:$I$203<>"Consulta")*RESERVAS!$T$6:$T$203*(((RESERVAS!$D$6:$D$203<DATE($B$3,11,1))*RESERVAS!$D$6:$D$203+(RESERVAS!$D$6:$D$203>=DATE($B$3,11,1))*DATE($B$3,11,1))-((RESERVAS!$C$6:$C$203>DATE($B$3,10,1))*RESERVAS!$C$6:$C$203+(RESERVAS!$C$6:$C$203<=DATE($B$3,10,1))*DATE($B$3,10,1)))) -> 0 | H22: =SUMIFS('DESPESAS CASA'!$D$6:$D$305,'DESPESAS CASA'!$A$6:$A$305,">="&DATE($B$3,10,1),'DESPESAS CASA'!$A$6:$A$305,"<"&DATE($B$3,11,1),'DESPESAS CASA'!$E$6:$E$305,"") -> 0 | I22: =F22-G22-H22 -> 4909.675 | J22: =IF(F22=0,0,I22/F22) -> 1
A23: Novembro | B23: =DAY(EOMONTH(DATE($B$3,11,1),0))*2 -> 60 | C23: =SUMPRODUCT((RESERVAS!$C$6:$C$203<DATE($B$3,12,1))*(RESERVAS!$D$6:$D$203>DATE($B$3,11,1))*(RESERVAS!$I$6:$I$203<>"Cancelada")*(RESERVAS!$I$6:$I$203<>"Consulta")*(((RESERVAS!$D$6:$D$203<DATE($B$3,12,1))*RESERVAS!$D$6:$D$203+(RESERVAS!$D$6:$D$203>=DATE($B$3,12,1))*DATE($B$3,12,1))-((RESERVAS!$C$6:$C$203>DATE($B$3,11,1))*RESERVAS!$C$6:$C$203+(RESERVAS!$C$6:$C$203<=DATE($B$3,11,1))*DATE($B$3,11,1)))) -> 17 | D23: =MAX(0,B23-C23) -> 43 | E23: =IF(B23=0,0,C23/B23) -> 0.28333333 | F23: =SUMPRODUCT((RESERVAS!$C$6:$C$203<DATE($B$3,12,1))*(RESERVAS!$D$6:$D$203>DATE($B$3,11,1))*(RESERVAS!$I$6:$I$203<>"Cancelada")*(RESERVAS!$I$6:$I$203<>"Consulta")*RESERVAS!$F$6:$F$203*(((RESERVAS!$D$6:$D$203<DATE($B$3,12,1))*RESERVAS!$D$6:$D$203+(RESERVAS!$D$6:$D$203>=DATE($B$3,12,1))*DATE($B$3,12,1))-((RESERVAS!$C$6:$C$203>DATE($B$3,11,1))*RESERVAS!$C$6:$C$203+(RESERVAS!$C$6:$C$203<=DATE($B$3,11,1))*DATE($B$3,11,1)))) -> 7431.995 | G23: =SUMPRODUCT((RESERVAS!$C$6:$C$203<DATE($B$3,12,1))*(RESERVAS!$D$6:$D$203>DATE($B$3,11,1))*(RESERVAS!$I$6:$I$203<>"Cancelada")*(RESERVAS!$I$6:$I$203<>"Consulta")*RESERVAS!$T$6:$T$203*(((RESERVAS!$D$6:$D$203<DATE($B$3,12,1))*RESERVAS!$D$6:$D$203+(RESERVAS!$D$6:$D$203>=DATE($B$3,12,1))*DATE($B$3,12,1))-((RESERVAS!$C$6:$C$203>DATE($B$3,11,1))*RESERVAS!$C$6:$C$203+(RESERVAS!$C$6:$C$203<=DATE($B$3,11,1))*DATE($B$3,11,1)))) -> 0 | H23: =SUMIFS('DESPESAS CASA'!$D$6:$D$305,'DESPESAS CASA'!$A$6:$A$305,">="&DATE($B$3,11,1),'DESPESAS CASA'!$A$6:$A$305,"<"&DATE($B$3,12,1),'DESPESAS CASA'!$E$6:$E$305,"") -> 0 | I23: =F23-G23-H23 -> 7431.995 | J23: =IF(F23=0,0,I23/F23) -> 1
A24: Dezembro | B24: =DAY(EOMONTH(DATE($B$3,12,1),0))*2 -> 62 | C24: =SUMPRODUCT((RESERVAS!$C$6:$C$203<DATE($B$3,13,1))*(RESERVAS!$D$6:$D$203>DATE($B$3,12,1))*(RESERVAS!$I$6:$I$203<>"Cancelada")*(RESERVAS!$I$6:$I$203<>"Consulta")*(((RESERVAS!$D$6:$D$203<DATE($B$3,13,1))*RESERVAS!$D$6:$D$203+(RESERVAS!$D$6:$D$203>=DATE($B$3,13,1))*DATE($B$3,13,1))-((RESERVAS!$C$6:$C$203>DATE($B$3,12,1))*RESERVAS!$C$6:$C$203+(RESERVAS!$C$6:$C$203<=DATE($B$3,12,1))*DATE($B$3,12,1)))) -> 16 | D24: =MAX(0,B24-C24) -> 46 | E24: =IF(B24=0,0,C24/B24) -> 0.25806452 | F24: =SUMPRODUCT((RESERVAS!$C$6:$C$203<DATE($B$3,13,1))*(RESERVAS!$D$6:$D$203>DATE($B$3,12,1))*(RESERVAS!$I$6:$I$203<>"Cancelada")*(RESERVAS!$I$6:$I$203<>"Consulta")*RESERVAS!$F$6:$F$203*(((RESERVAS!$D$6:$D$203<DATE($B$3,13,1))*RESERVAS!$D$6:$D$203+(RESERVAS!$D$6:$D$203>=DATE($B$3,13,1))*DATE($B$3,13,1))-((RESERVAS!$C$6:$C$203>DATE($B$3,12,1))*RESERVAS!$C$6:$C$203+(RESERVAS!$C$6:$C$203<=DATE($B$3,12,1))*DATE($B$3,12,1)))) -> 13400 | G24: =SUMPRODUCT((RESERVAS!$C$6:$C$203<DATE($B$3,13,1))*(RESERVAS!$D$6:$D$203>DATE($B$3,12,1))*(RESERVAS!$I$6:$I$203<>"Cancelada")*(RESERVAS!$I$6:$I$203<>"Consulta")*RESERVAS!$T$6:$T$203*(((RESERVAS!$D$6:$D$203<DATE($B$3,13,1))*RESERVAS!$D$6:$D$203+(RESERVAS!$D$6:$D$203>=DATE($B$3,13,1))*DATE($B$3,13,1))-((RESERVAS!$C$6:$C$203>DATE($B$3,12,1))*RESERVAS!$C$6:$C$203+(RESERVAS!$C$6:$C$203<=DATE($B$3,12,1))*DATE($B$3,12,1)))) -> 0 | H24: =SUMIFS('DESPESAS CASA'!$D$6:$D$305,'DESPESAS CASA'!$A$6:$A$305,">="&DATE($B$3,12,1),'DESPESAS CASA'!$A$6:$A$305,"<"&DATE($B$3,13,1),'DESPESAS CASA'!$E$6:$E$305,"") -> 0 | I24: =F24-G24-H24 -> 13400 | J24: =IF(F24=0,0,I24/F24) -> 1

Sheet AGENDA
A1: AGENDA — DISPONIBILIDADE DA CASA
A2: Mês | B2: Setembro | D2: Ano | E2: 2026 | J2: Nº mês | K2: =MATCH(B2,LISTAS!$A$4:$A$15,0) -> 9
A4: SEG | B4: TER | C4: QUA | D4: QUI | E4: SEX | F4: SÁB | G4: DOM | I4: RESUMO DO MÊS
A5: =IF(MONTH((DATE($E$2,$K$2,1)-WEEKDAY(DATE($E$2,$K$2,1),2)+1+0))<>$K$2,"",TEXT((DATE($E$2,$K$2,1)-WEEKDAY(DATE($E$2,$K$2,1),2)+1+0),"dd")&CHAR(10)&IF(COUNTIFS(RESERVAS!$C$6:$C$203,"<="&(DATE($E$2,$K$2,1)-WEEKDAY(DATE($E$2,$K$2,1),2)+1+0),RESERVAS!$D$6:$D$203,">"&(DATE($E$2,$K$2,1)-WEEKDAY(DATE($E$2,$K$2,1),2)+1+0),RESERVAS!$I$6:$I$203,"<>Cancelada",RESERVAS!$I$6:$I$203,"<>Consulta")=0,"DISPONÍVEL",IF(COUNTIFS(RESERVAS!$C$6:$C$203,"<="&(DATE($E$2,$K$2,1)-WEEKDAY(DATE($E$2,$K$2,1),2)+1+0),RESERVAS!$D$6:$D$203,">"&(DATE($E$2,$K$2,1)-WEEKDAY(DATE($E$2,$K$2,1),2)+1+0),RESERVAS!$I$6:$I$203,"<>Cancelada",RESERVAS!$I$6:$I$203,"<>Consulta")=1,"ALUGADA","CONFLITO"))&IF(COUNTIFS(RESERVAS!$C$6:$C$203,"<="&(DATE($E$2,$K$2,1)-WEEKDAY(DATE($E$2,$K$2,1),2)+1+0),RESERVAS!$D$6:$D$203,">"&(DATE($E$2,$K$2,1)-WEEKDAY(DATE($E$2,$K$2,1),2)+1+0),RESERVAS!$I$6:$I$203,"<>Cancelada",RESERVAS!$I$6:$I$203,"<>Consulta")=0,"",CHAR(10)&IFERROR(LOOKUP(2,1/((RESERVAS!$C$6:$C$203<=(DATE($E$2,$K$2,1)-WEEKDAY(DATE($E$2,$K$2,1),2)+1+0))*(RESERVAS!$D$6:$D$203>(DATE($E$2,$K$2,1)-WEEKDAY(DATE($E$2,$K$2,1),2)+1+0))*(RESERVAS!$I$6:$I$203<>"Cancelada")*(RESERVAS!$I$6:$I$203<>"Consulta")),RESERVAS!$B$6:$B$203),""))) | B5: =IF(MONTH((DATE($E$2,$K$2,1)-WEEKDAY(DATE($E$2,$K$2,1),2)+1+1))<>$K$2,"",TEXT((DATE($E$2,$K$2,1)-WEEKDAY(DATE($E$2,$K$2,1),2)+1+1),"dd")&CHAR(10)&IF(COUNTIFS(RESERVAS!$C$6:$C$203,"<="&(DATE($E$2,$K$2,1)-WEEKDAY(DATE($E$2,$K$2,1),2)+1+1),RESERVAS!$D$6:$D$203,">"&(DATE($E$2,$K$2,1)-WEEKDAY(DATE($E$2,$K$2,1),2)+1+1),RESERVAS!$I$6:$I$203,"<>Cancelada",RESERVAS!$I$6:$I$203,"<>Consulta")=0,"DISPONÍVEL",IF(COUNTIFS(RESERVAS!$C$6:$C$203,"<="&(DATE($E$2,$K$2,1)-WEEKDAY(DATE($E$2,$K$2,1),2)+1+1),RESERVAS!$D$6:$D$203,">"&(DATE($E$2,$K$2,1)-WEEKDAY(DATE($E$2,$K$2,1),2)+1+1),RESERVAS!$I$6:$I$203,"<>Cancelada",RESERVAS!$I$6:$I$203,"<>Consulta")=1,"ALUGADA","CONFLITO"))&IF(COUNTIFS(RESERVAS!$C$6:$C$203,"<="&(DATE($E$2,$K$2,1)-WEEKDAY(DATE($E$2,$K$2,1),2)+1+1),RESERVAS!$D$6:$D$203,">"&(DATE($E$2,$K$2,1)-WEEKDAY(DATE($E$2,$K$2,1),2)+1+1),RESERVAS!$I$6:$I$203,"<>Cancelada",RESERVAS!$I$6:$I$203,"<>Consulta")=0,"",CHAR(10)&IFERROR(LOOKUP(2,1/((RESERVAS!$C$6:$C$203<=(DATE($E$2,$K$2,1)-WEEKDAY(DATE($E$2,$K$2,1),2)+1+1))*(RESERVAS!$D$6:$D$203>(DATE($E$2,$K$2,1)-WEEKDAY(DATE($E$2,$K$2,1),2)+1+1))*(RESERVAS!$I$6:$I$203<>"Cancelada")*(RESERVAS!$I$6:$I$203<>"Consulta")),RESERVAS!$B$6:$B$203),""))) -> 01 DISPONÍVEL | C5: =IF(MONTH((DATE($E$2,$K$2,1)-WEEKDAY(DATE($E$2,$K$2,1),2)+1+2))<>$K$2,"",TEXT((DATE($E$2,$K$2,1)-WEEKDAY(DATE($E$2,$K$2,1),2)+1+2),"dd")&CHAR(10)&IF(COUNTIFS(RESERVAS!$C$6:$C$203,"<="&(DATE($E$2,$K$2,1)-WEEKDAY(DATE($E$2,$K$2,1),2)+1+2),RESERVAS!$D$6:$D$203,">"&(DATE($E$2,$K$2,1)-WEEKDAY(DATE($E$2,$K$2,1),2)+1+2),RESERVAS!$I$6:$I$203,"<>Cancelada",RESERVAS!$I$6:$I$203,"<>Consulta")=0,"DISPONÍVEL",IF(COUNTIFS(RESERVAS!$C$6:$C$203,"<="&(DATE($E$2,$K$2,1)-WEEKDAY(DATE($E$2,$K$2,1),2)+1+2),RESERVAS!$D$6:$D$203,">"&(DATE($E$2,$K$2,1)-WEEKDAY(DATE($E$2,$K$2,1),2)+1+2),RESERVAS!$I$6:$I$203,"<>Cancelada",RESERVAS!$I$6:$I$203,"<>Consulta")=1,"ALUGADA","CONFLITO"))&IF(COUNTIFS(RESERVAS!$C$6:$C$203,"<="&(DATE($E$2,$K$2,1)-WEEKDAY(DATE($E$2,$K$2,1),2)+1+2),RESERVAS!$D$6:$D$203,">"&(DATE($E$2,$K$2,1)-WEEKDAY(DATE($E$2,$K$2,1),2)+1+2),RESERVAS!$I$6:$I$203,"<>Cancelada",RESERVAS!$I$6:$I$203,"<>Consulta")=0,"",CHAR(10)&IFERROR(LOOKUP(2,1/((RESERVAS!$C$6:$C$203<=(DATE($E$2,$K$2,1)-WEEKDAY(DATE($E$2,$K$2,1),2)+1+2))*(RESERVAS!$D$6:$D$203>(DATE($E$2,$K$2,1)-WEEKDAY(DATE($E$2,$K$2,1),2)+1+2))*(RESERVAS!$I$6:$I$203<>"Cancelada")*(RESERVAS!$I$6:$I$203<>"Consulta")),RESERVAS!$B$6:$B$203),""))) -> 02 DISPONÍVEL | D5: =IF(MONTH((DATE($E$2,$K$2,1)-WEEKDAY(DATE($E$2,$K$2,1),2)+1+3))<>$K$2,"",TEXT((DATE($E$2,$K$2,1)-WEEKDAY(DATE($E$2,$K$2,1),2)+1+3),"dd")&CHAR(10)&IF(COUNTIFS(RESERVAS!$C$6:$C$203,"<="&(DATE($E$2,$K$2,1)-WEEKDAY(DATE($E$2,$K$2,1),2)+1+3),RESERVAS!$D$6:$D$203,">"&(DATE($E$2,$K$2,1)-WEEKDAY(DATE($E$2,$K$2,1),2)+1+3),RESERVAS!$I$6:$I$203,"<>Cancelada",RESERVAS!$I$6:$I$203,"<>Consulta")=0,"DISPONÍVEL",IF(COUNTIFS(RESERVAS!$C$6:$C$203,"<="&(DATE($E$2,$K$2,1)-WEEKDAY(DATE($E$2,$K$2,1),2)+1+3),RESERVAS!$D$6:$D$203,">"&(DATE($E$2,$K$2,1)-WEEKDAY(DATE($E$2,$K$2,1),2)+1+3),RESERVAS!$I$6:$I$203,"<>Cancelada",RESERVAS!$I$6:$I$203,"<>Consulta")=1,"ALUGADA","CONFLITO"))&IF(COUNTIFS(RESERVAS!$C$6:$C$203,"<="&(DATE($E$2,$K$2,1)-WEEKDAY(DATE($E$2,$K$2,1),2)+1+3),RESERVAS!$D$6:$D$203,">"&(DATE($E$2,$K$2,1)-WEEKDAY(DATE($E$2,$K$2,1),2)+1+3),RESERVAS!$I$6:$I$203,"<>Cancelada",RESERVAS!$I$6:$I$203,"<>Consulta")=0,"",CHAR(10)&IFERROR(LOOKUP(2,1/((RESERVAS!$C$6:$C$203<=(DATE($E$2,$K$2,1)-WEEKDAY(DATE($E$2,$K$2,1),2)+1+3))*(RESERVAS!$D$6:$D$203>(DATE($E$2,$K$2,1)-WEEKDAY(DATE($E$2,$K$2,1),2)+1+3))*(RESERVAS!$I$6:$I$203<>"Cancelada")*(RESERVAS!$I$6:$I$203<>"Consulta")),RESERVAS!$B$6:$B$203),""))) -> 03 DISPONÍVEL | E5: =IF(MONTH((DATE($E$2,$K$2,1)-WEEKDAY(DATE($E$2,$K$2,1),2)+1+4))<>$K$2,"",TEXT((DATE($E$2,$K$2,1)-WEEKDAY(DATE($E$2,$K$2,1),2)+1+4),"dd")&CHAR(10)&IF(COUNTIFS(RESERVAS!$C$6:$C$203,"<="&(DATE($E$2,$K$2,1)-WEEKDAY(DATE($E$2,$K$2,1),2)+1+4),RESERVAS!$D$6:$D$203,">"&(DATE($E$2,$K$2,1)-WEEKDAY(DATE($E$2,$K$2,1),2)+1+4),RESERVAS!$I$6:$I$203,"<>Cancelada",RESERVAS!$I$6:$I$203,"<>Consulta")=0,"DISPONÍVEL",IF(COUNTIFS(RESERVAS!$C$6:$C$203,"<="&(DATE($E$2,$K$2,1)-WEEKDAY(DATE($E$2,$K$2,1),2)+1+4),RESERVAS!$D$6:$D$203,">"&(DATE($E$2,$K$2,1)-WEEKDAY(DATE($E$2,$K$2,1),2)+1+4),RESERVAS!$I$6:$I$203,"<>Cancelada",RESERVAS!$I$6:$I$203,"<>Consulta")=1,"ALUGADA","CONFLITO"))&IF(COUNTIFS(RESERVAS!$C$6:$C$203,"<="&(DATE($E$2,$K$2,1)-WEEKDAY(DATE($E$2,$K$2,1),2)+1+4),RESERVAS!$D$6:$D$203,">"&(DATE($E$2,$K$2,1)-WEEKDAY(DATE($E$2,$K$2,1),2)+1+4),RESERVAS!$I$6:$I$203,"<>Cancelada",RESERVAS!$I$6:$I$203,"<>Consulta")=0,"",CHAR(10)&IFERROR(LOOKUP(2,1/((RESERVAS!$C$6:$C$203<=(DATE($E$2,$K$2,1)-WEEKDAY(DATE($E$2,$K$2,1),2)+1+4))*(RESERVAS!$D$6:$D$203>(DATE($E$2,$K$2,1)-WEEKDAY(DATE($E$2,$K$2,1),2)+1+4))*(RESERVAS!$I$6:$I$203<>"Cancelada")*(RESERVAS!$I$6:$I$203<>"Consulta")),RESERVAS!$B$6:$B$203),""))) -> 04 ALUGADA Regina - 7 de Setembro | F5: =IF(MONTH((DATE($E$2,$K$2,1)-WEEKDAY(DATE($E$2,$K$2,1),2)+1+5))<>$K$2,"",TEXT((DATE($E$2,$K$2,1)-WEEKDAY(DATE($E$2,$K$2,1),2)+1+5),"dd")&CHAR(10)&IF(COUNTIFS(RESERVAS!$C$6:$C$203,"<="&(DATE($E$2,$K$2,1)-WEEKDAY(DATE($E$2,$K$2,1),2)+1+5),RESERVAS!$D$6:$D$203,">"&(DATE($E$2,$K$2,1)-WEEKDAY(DATE($E$2,$K$2,1),2)+1+5),RESERVAS!$I$6:$I$203,"<>Cancelada",RESERVAS!$I$6:$I$203,"<>Consulta")=0,"DISPONÍVEL",IF(COUNTIFS(RESERVAS!$C$6:$C$203,"<="&(DATE($E$2,$K$2,1)-WEEKDAY(DATE($E$2,$K$2,1),2)+1+5),RESERVAS!$D$6:$D$203,">"&(DATE($E$2,$K$2,1)-WEEKDAY(DATE($E$2,$K$2,1),2)+1+5),RESERVAS!$I$6:$I$203,"<>Cancelada",RESERVAS!$I$6:$I$203,"<>Consulta")=1,"ALUGADA","CONFLITO"))&IF(COUNTIFS(RESERVAS!$C$6:$C$203,"<="&(DATE($E$2,$K$2,1)-WEEKDAY(DATE($E$2,$K$2,1),2)+1+5),RESERVAS!$D$6:$D$203,">"&(DATE($E$2,$K$2,1)-WEEKDAY(DATE($E$2,$K$2,1),2)+1+5),RESERVAS!$I$6:$I$203,"<>Cancelada",RESERVAS!$I$6:$I$203,"<>Consulta")=0,"",CHAR(10)&IFERROR(LOOKUP(2,1/((RESERVAS!$C$6:$C$203<=(DATE($E$2,$K$2,1)-WEEKDAY(DATE($E$2,$K$2,1),2)+1+5))*(RESERVAS!$D$6:$D$203>(DATE($E$2,$K$2,1)-WEEKDAY(DATE($E$2,$K$2,1),2)+1+5))*(RESERVAS!$I$6:$I$203<>"Cancelada")*(RESERVAS!$I$6:$I$203<>"Consulta")),RESERVAS!$B$6:$B$203),""))) -> 05 ALUGADA Regina - 7 de Setembro | G5: =IF(MONTH((DATE($E$2,$K$2,1)-WEEKDAY(DATE($E$2,$K$2,1),2)+1+6))<>$K$2,"",TEXT((DATE($E$2,$K$2,1)-WEEKDAY(DATE($E$2,$K$2,1),2)+1+6),"dd")&CHAR(10)&IF(COUNTIFS(RESERVAS!$C$6:$C$203,"<="&(DATE($E$2,$K$2,1)-WEEKDAY(DATE($E$2,$K$2,1),2)+1+6),RESERVAS!$D$6:$D$203,">"&(DATE($E$2,$K$2,1)-WEEKDAY(DATE($E$2,$K$2,1),2)+1+6),RESERVAS!$I$6:$I$203,"<>Cancelada",RESERVAS!$I$6:$I$203,"<>Consulta")=0,"DISPONÍVEL",IF(COUNTIFS(RESERVAS!$C$6:$C$203,"<="&(DATE($E$2,$K$2,1)-WEEKDAY(DATE($E$2,$K$2,1),2)+1+6),RESERVAS!$D$6:$D$203,">"&(DATE($E$2,$K$2,1)-WEEKDAY(DATE($E$2,$K$2,1),2)+1+6),RESERVAS!$I$6:$I$203,"<>Cancelada",RESERVAS!$I$6:$I$203,"<>Consulta")=1,"ALUGADA","CONFLITO"))&IF(COUNTIFS(RESERVAS!$C$6:$C$203,"<="&(DATE($E$2,$K$2,1)-WEEKDAY(DATE($E$2,$K$2,1),2)+1+6),RESERVAS!$D$6:$D$203,">"&(DATE($E$2,$K$2,1)-WEEKDAY(DATE($E$2,$K$2,1),2)+1+6),RESERVAS!$I$6:$I$203,"<>Cancelada",RESERVAS!$I$6:$I$203,"<>Consulta")=0,"",CHAR(10)&IFERROR(LOOKUP(2,1/((RESERVAS!$C$6:$C$203<=(DATE($E$2,$K$2,1)-WEEKDAY(DATE($E$2,$K$2,1),2)+1+6))*(RESERVAS!$D$6:$D$203>(DATE($E$2,$K$2,1)-WEEKDAY(DATE($E$2,$K$2,1),2)+1+6))*(RESERVAS!$I$6:$I$203<>"Cancelada")*(RESERVAS!$I$6:$I$203<>"Consulta")),RESERVAS!$B$6:$B$203),""))) -> 06 ALUGADA Regina - 7 de Setembro | I5: Receita (R$) | J5: =SUMPRODUCT((RESERVAS!$C$6:$C$203<DATE($E$2,$K$2+1,1))*(RESERVAS!$D$6:$D$203>DATE($E$2,$K$2,1))*(RESERVAS!$I$6:$I$203<>"Cancelada")*(RESERVAS!$I$6:$I$203<>"Consulta")*RESERVAS!$F$6:$F$203*(((RESERVAS!$D$6:$D$203<DATE($E$2,$K$2+1,1))*RESERVAS!$D$6:$D$203+(RESERVAS!$D$6:$D$203>=DATE($E$2,$K$2+1,1))*DATE($E$2,$K$2+1,1))-((RESERVAS!$C$6:$C$203>DATE($E$2,$K$2,1))*RESERVAS!$C$6:$C$203+(RESERVAS!$C$6:$C$203<=DATE($E$2,$K$2,1))*DATE($E$2,$K$2,1)))) -> 2800
A6: =IF(MONTH((DATE($E$2,$K$2,1)-WEEKDAY(DATE($E$2,$K$2,1),2)+1+7))<>$K$2,"",TEXT((DATE($E$2,$K$2,1)-WEEKDAY(DATE($E$2,$K$2,1),2)+1+7),"dd")&CHAR(10)&IF(COUNTIFS(RESERVAS!$C$6:$C$203,"<="&(DATE($E$2,$K$2,1)-WEEKDAY(DATE($E$2,$K$2,1),2)+1+7),RESERVAS!$D$6:$D$203,">"&(DATE($E$2,$K$2,1)-WEEKDAY(DATE($E$2,$K$2,1),2)+1+7),RESERVAS!$I$6:$I$203,"<>Cancelada",RESERVAS!$I$6:$I$203,"<>Consulta")=0,"DISPONÍVEL",IF(COUNTIFS(RESERVAS!$C$6:$C$203,"<="&(DATE($E$2,$K$2,1)-WEEKDAY(DATE($E$2,$K$2,1),2)+1+7),RESERVAS!$D$6:$D$203,">"&(DATE($E$2,$K$2,1)-WEEKDAY(DATE($E$2,$K$2,1),2)+1+7),RESERVAS!$I$6:$I$203,"<>Cancelada",RESERVAS!$I$6:$I$203,"<>Consulta")=1,"ALUGADA","CONFLITO"))&IF(COUNTIFS(RESERVAS!$C$6:$C$203,"<="&(DATE($E$2,$K$2,1)-WEEKDAY(DATE($E$2,$K$2,1),2)+1+7),RESERVAS!$D$6:$D$203,">"&(DATE($E$2,$K$2,1)-WEEKDAY(DATE($E$2,$K$2,1),2)+1+7),RESERVAS!$I$6:$I$203,"<>Cancelada",RESERVAS!$I$6:$I$203,"<>Consulta")=0,"",CHAR(10)&IFERROR(LOOKUP(2,1/((RESERVAS!$C$6:$C$203<=(DATE($E$2,$K$2,1)-WEEKDAY(DATE($E$2,$K$2,1),2)+1+7))*(RESERVAS!$D$6:$D$203>(DATE($E$2,$K$2,1)-WEEKDAY(DATE($E$2,$K$2,1),2)+1+7))*(RESERVAS!$I$6:$I$203<>"Cancelada")*(RESERVAS!$I$6:$I$203<>"Consulta")),RESERVAS!$B$6:$B$203),""))) -> 07 ALUGADA Regina - 7 de Setembro | B6: =IF(MONTH((DATE($E$2,$K$2,1)-WEEKDAY(DATE($E$2,$K$2,1),2)+1+8))<>$K$2,"",TEXT((DATE($E$2,$K$2,1)-WEEKDAY(DATE($E$2,$K$2,1),2)+1+8),"dd")&CHAR(10)&IF(COUNTIFS(RESERVAS!$C$6:$C$203,"<="&(DATE($E$2,$K$2,1)-WEEKDAY(DATE($E$2,$K$2,1),2)+1+8),RESERVAS!$D$6:$D$203,">"&(DATE($E$2,$K$2,1)-WEEKDAY(DATE($E$2,$K$2,1),2)+1+8),RESERVAS!$I$6:$I$203,"<>Cancelada",RESERVAS!$I$6:$I$203,"<>Consulta")=0,"DISPONÍVEL",IF(COUNTIFS(RESERVAS!$C$6:$C$203,"<="&(DATE($E$2,$K$2,1)-WEEKDAY(DATE($E$2,$K$2,1),2)+1+8),RESERVAS!$D$6:$D$203,">"&(DATE($E$2,$K$2,1)-WEEKDAY(DATE($E$2,$K$2,1),2)+1+8),RESERVAS!$I$6:$I$203,"<>Cancelada",RESERVAS!$I$6:$I$203,"<>Consulta")=1,"ALUGADA","CONFLITO"))&IF(COUNTIFS(RESERVAS!$C$6:$C$203,"<="&(DATE($E$2,$K$2,1)-WEEKDAY(DATE($E$2,$K$2,1),2)+1+8),RESERVAS!$D$6:$D$203,">"&(DATE($E$2,$K$2,1)-WEEKDAY(DATE($E$2,$K$2,1),2)+1+8),RESERVAS!$I$6:$I$203,"<>Cancelada",RESERVAS!$I$6:$I$203,"<>Consulta")=0,"",CHAR(10)&IFERROR(LOOKUP(2,1/((RESERVAS!$C$6:$C$203<=(DATE($E$2,$K$2,1)-WEEKDAY(DATE($E$2,$K$2,1),2)+1+8))*(RESERVAS!$D$6:$D$203>(DATE($E$2,$K$2,1)-WEEKDAY(DATE($E$2,$K$2,1),2)+1+8))*(RESERVAS!$I$6:$I$203<>"Cancelada")*(RESERVAS!$I$6:$I$203<>"Consulta")),RESERVAS!$B$6:$B$203),""))) -> 08 DISPONÍVEL | C6: =IF(MONTH((DATE($E$2,$K$2,1)-WEEKDAY(DATE($E$2,$K$2,1),2)+1+9))<>$K$2,"",TEXT((DATE($E$2,$K$2,1)-WEEKDAY(DATE($E$2,$K$2,1),2)+1+9),"dd")&CHAR(10)&IF(COUNTIFS(RESERVAS!$C$6:$C$203,"<="&(DATE($E$2,$K$2,1)-WEEKDAY(DATE($E$2,$K$2,1),2)+1+9),RESERVAS!$D$6:$D$203,">"&(DATE($E$2,$K$2,1)-WEEKDAY(DATE($E$2,$K$2,1),2)+1+9),RESERVAS!$I$6:$I$203,"<>Cancelada",RESERVAS!$I$6:$I$203,"<>Consulta")=0,"DISPONÍVEL",IF(COUNTIFS(RESERVAS!$C$6:$C$203,"<="&(DATE($E$2,$K$2,1)-WEEKDAY(DATE($E$2,$K$2,1),2)+1+9),RESERVAS!$D$6:$D$203,">"&(DATE($E$2,$K$2,1)-WEEKDAY(DATE($E$2,$K$2,1),2)+1+9),RESERVAS!$I$6:$I$203,"<>Cancelada",RESERVAS!$I$6:$I$203,"<>Consulta")=1,"ALUGADA","CONFLITO"))&IF(COUNTIFS(RESERVAS!$C$6:$C$203,"<="&(DATE($E$2,$K$2,1)-WEEKDAY(DATE($E$2,$K$2,1),2)+1+9),RESERVAS!$D$6:$D$203,">"&(DATE($E$2,$K$2,1)-WEEKDAY(DATE($E$2,$K$2,1),2)+1+9),RESERVAS!$I$6:$I$203,"<>Cancelada",RESERVAS!$I$6:$I$203,"<>Consulta")=0,"",CHAR(10)&IFERROR(LOOKUP(2,1/((RESERVAS!$C$6:$C$203<=(DATE($E$2,$K$2,1)-WEEKDAY(DATE($E$2,$K$2,1),2)+1+9))*(RESERVAS!$D$6:$D$203>(DATE($E$2,$K$2,1)-WEEKDAY(DATE($E$2,$K$2,1),2)+1+9))*(RESERVAS!$I$6:$I$203<>"Cancelada")*(RESERVAS!$I$6:$I$203<>"Consulta")),RESERVAS!$B$6:$B$203),""))) -> 09 DISPONÍVEL | D6: =IF(MONTH((DATE($E$2,$K$2,1)-WEEKDAY(DATE($E$2,$K$2,1),2)+1+10))<>$K$2,"",TEXT((DATE($E$2,$K$2,1)-WEEKDAY(DATE($E$2,$K$2,1),2)+1+10),"dd")&CHAR(10)&IF(COUNTIFS(RESERVAS!$C$6:$C$203,"<="&(DATE($E$2,$K$2,1)-WEEKDAY(DATE($E$2,$K$2,1),2)+1+10),RESERVAS!$D$6:$D$203,">"&(DATE($E$2,$K$2,1)-WEEKDAY(DATE($E$2,$K$2,1),2)+1+10),RESERVAS!$I$6:$I$203,"<>Cancelada",RESERVAS!$I$6:$I$203,"<>Consulta")=0,"DISPONÍVEL",IF(COUNTIFS(RESERVAS!$C$6:$C$203,"<="&(DATE($E$2,$K$2,1)-WEEKDAY(DATE($E$2,$K$2,1),2)+1+10),RESERVAS!$D$6:$D$203,">"&(DATE($E$2,$K$2,1)-WEEKDAY(DATE($E$2,$K$2,1),2)+1+10),RESERVAS!$I$6:$I$203,"<>Cancelada",RESERVAS!$I$6:$I$203,"<>Consulta")=1,"ALUGADA","CONFLITO"))&IF(COUNTIFS(RESERVAS!$C$6:$C$203,"<="&(DATE($E$2,$K$2,1)-WEEKDAY(DATE($E$2,$K$2,1),2)+1+10),RESERVAS!$D$6:$D$203,">"&(DATE($E$2,$K$2,1)-WEEKDAY(DATE($E$2,$K$2,1),2)+1+10),RESERVAS!$I$6:$I$203,"<>Cancelada",RESERVAS!$I$6:$I$203,"<>Consulta")=0,"",CHAR(10)&IFERROR(LOOKUP(2,1/((RESERVAS!$C$6:$C$203<=(DATE($E$2,$K$2,1)-WEEKDAY(DATE($E$2,$K$2,1),2)+1+10))*(RESERVAS!$D$6:$D$203>(DATE($E$2,$K$2,1)-WEEKDAY(DATE($E$2,$K$2,1),2)+1+10))*(RESERVAS!$I$6:$I$203<>"Cancelada")*(RESERVAS!$I$6:$I$203<>"Consulta")),RESERVAS!$B$6:$B$203),""))) -> 10 DISPONÍVEL | E6: =IF(MONTH((DATE($E$2,$K$2,1)-WEEKDAY(DATE($E$2,$K$2,1),2)+1+11))<>$K$2,"",TEXT((DATE($E$2,$K$2,1)-WEEKDAY(DATE($E$2,$K$2,1),2)+1+11),"dd")&CHAR(10)&IF(COUNTIFS(RESERVAS!$C$6:$C$203,"<="&(DATE($E$2,$K$2,1)-WEEKDAY(DATE($E$2,$K$2,1),2)+1+11),RESERVAS!$D$6:$D$203,">"&(DATE($E$2,$K$2,1)-WEEKDAY(DATE($E$2,$K$2,1),2)+1+11),RESERVAS!$I$6:$I$203,"<>Cancelada",RESERVAS!$I$6:$I$203,"<>Consulta")=0,"DISPONÍVEL",IF(COUNTIFS(RESERVAS!$C$6:$C$203,"<="&(DATE($E$2,$K$2,1)-WEEKDAY(DATE($E$2,$K$2,1),2)+1+11),RESERVAS!$D$6:$D$203,">"&(DATE($E$2,$K$2,1)-WEEKDAY(DATE($E$2,$K$2,1),2)+1+11),RESERVAS!$I$6:$I$203,"<>Cancelada",RESERVAS!$I$6:$I$203,"<>Consulta")=1,"ALUGADA","CONFLITO"))&IF(COUNTIFS(RESERVAS!$C$6:$C$203,"<="&(DATE($E$2,$K$2,1)-WEEKDAY(DATE($E$2,$K$2,1),2)+1+11),RESERVAS!$D$6:$D$203,">"&(DATE($E$2,$K$2,1)-WEEKDAY(DATE($E$2,$K$2,1),2)+1+11),RESERVAS!$I$6:$I$203,"<>Cancelada",RESERVAS!$I$6:$I$203,"<>Consulta")=0,"",CHAR(10)&IFERROR(LOOKUP(2,1/((RESERVAS!$C$6:$C$203<=(DATE($E$2,$K$2,1)-WEEKDAY(DATE($E$2,$K$2,1),2)+1+11))*(RESERVAS!$D$6:$D$203>(DATE($E$2,$K$2,1)-WEEKDAY(DATE($E$2,$K$2,1),2)+1+11))*(RESERVAS!$I$6:$I$203<>"Cancelada")*(RESERVAS!$I$6:$I$203<>"Consulta")),RESERVAS!$B$6:$B$203),""))) -> 11 ALUGADA Louis Renan - Férias | F6: =IF(MONTH((DATE($E$2,$K$2,1)-WEEKDAY(DATE($E$2,$K$2,1),2)+1+12))<>$K$2,"",TEXT((DATE($E$2,$K$2,1)-WEEKDAY(DATE($E$2,$K$2,1),2)+1+12),"dd")&CHAR(10)&IF(COUNTIFS(RESERVAS!$C$6:$C$203,"<="&(DATE($E$2,$K$2,1)-WEEKDAY(DATE($E$2,$K$2,1),2)+1+12),RESERVAS!$D$6:$D$203,">"&(DATE($E$2,$K$2,1)-WEEKDAY(DATE($E$2,$K$2,1),2)+1+12),RESERVAS!$I$6:$I$203,"<>Cancelada",RESERVAS!$I$6:$I$203,"<>Consulta")=0,"DISPONÍVEL",IF(COUNTIFS(RESERVAS!$C$6:$C$203,"<="&(DATE($E$2,$K$2,1)-WEEKDAY(DATE($E$2,$K$2,1),2)+1+12),RESERVAS!$D$6:$D$203,">"&(DATE($E$2,$K$2,1)-WEEKDAY(DATE($E$2,$K$2,1),2)+1+12),RESERVAS!$I$6:$I$203,"<>Cancelada",RESERVAS!$I$6:$I$203,"<>Consulta")=1,"ALUGADA","CONFLITO"))&IF(COUNTIFS(RESERVAS!$C$6:$C$203,"<="&(DATE($E$2,$K$2,1)-WEEKDAY(DATE($E$2,$K$2,1),2)+1+12),RESERVAS!$D$6:$D$203,">"&(DATE($E$2,$K$2,1)-WEEKDAY(DATE($E$2,$K$2,1),2)+1+12),RESERVAS!$I$6:$I$203,"<>Cancelada",RESERVAS!$I$6:$I$203,"<>Consulta")=0,"",CHAR(10)&IFERROR(LOOKUP(2,1/((RESERVAS!$C$6:$C$203<=(DATE($E$2,$K$2,1)-WEEKDAY(DATE($E$2,$K$2,1),2)+1+12))*(RESERVAS!$D$6:$D$203>(DATE($E$2,$K$2,1)-WEEKDAY(DATE($E$2,$K$2,1),2)+1+12))*(RESERVAS!$I$6:$I$203<>"Cancelada")*(RESERVAS!$I$6:$I$203<>"Consulta")),RESERVAS!$B$6:$B$203),""))) -> 12 ALUGADA Louis Renan - Férias | G6: =IF(MONTH((DATE($E$2,$K$2,1)-WEEKDAY(DATE($E$2,$K$2,1),2)+1+13))<>$K$2,"",TEXT((DATE($E$2,$K$2,1)-WEEKDAY(DATE($E$2,$K$2,1),2)+1+13),"dd")&CHAR(10)&IF(COUNTIFS(RESERVAS!$C$6:$C$203,"<="&(DATE($E$2,$K$2,1)-WEEKDAY(DATE($E$2,$K$2,1),2)+1+13),RESERVAS!$D$6:$D$203,">"&(DATE($E$2,$K$2,1)-WEEKDAY(DATE($E$2,$K$2,1),2)+1+13),RESERVAS!$I$6:$I$203,"<>Cancelada",RESERVAS!$I$6:$I$203,"<>Consulta")=0,"DISPONÍVEL",IF(COUNTIFS(RESERVAS!$C$6:$C$203,"<="&(DATE($E$2,$K$2,1)-WEEKDAY(DATE($E$2,$K$2,1),2)+1+13),RESERVAS!$D$6:$D$203,">"&(DATE($E$2,$K$2,1)-WEEKDAY(DATE($E$2,$K$2,1),2)+1+13),RESERVAS!$I$6:$I$203,"<>Cancelada",RESERVAS!$I$6:$I$203,"<>Consulta")=1,"ALUGADA","CONFLITO"))&IF(COUNTIFS(RESERVAS!$C$6:$C$203,"<="&(DATE($E$2,$K$2,1)-WEEKDAY(DATE($E$2,$K$2,1),2)+1+13),RESERVAS!$D$6:$D$203,">"&(DATE($E$2,$K$2,1)-WEEKDAY(DATE($E$2,$K$2,1),2)+1+13),RESERVAS!$I$6:$I$203,"<>Cancelada",RESERVAS!$I$6:$I$203,"<>Consulta")=0,"",CHAR(10)&IFERROR(LOOKUP(2,1/((RESERVAS!$C$6:$C$203<=(DATE($E$2,$K$2,1)-WEEKDAY(DATE($E$2,$K$2,1),2)+1+13))*(RESERVAS!$D$6:$D$203>(DATE($E$2,$K$2,1)-WEEKDAY(DATE($E$2,$K$2,1),2)+1+13))*(RESERVAS!$I$6:$I$203<>"Cancelada")*(RESERVAS!$I$6:$I$203<>"Consulta")),RESERVAS!$B$6:$B$203),""))) -> 13 ALUGADA Louis Renan - Férias | I6: Custos diretos (R$) | J6: =SUMPRODUCT((RESERVAS!$C$6:$C$203<DATE($E$2,$K$2+1,1))*(RESERVAS!$D$6:$D$203>DATE($E$2,$K$2,1))*(RESERVAS!$I$6:$I$203<>"Cancelada")*(RESERVAS!$I$6:$I$203<>"Consulta")*RESERVAS!$T$6:$T$203*(((RESERVAS!$D$6:$D$203<DATE($E$2,$K$2+1,1))*RESERVAS!$D$6:$D$203+(RESERVAS!$D$6:$D$203>=DATE($E$2,$K$2+1,1))*DATE($E$2,$K$2+1,1))-((RESERVAS!$C$6:$C$203>DATE($E$2,$K$2,1))*RESERVAS!$C$6:$C$203+(RESERVAS!$C$6:$C$203<=DATE($E$2,$K$2,1))*DATE($E$2,$K$2,1)))) -> 32.05
A7: =IF(MONTH((DATE($E$2,$K$2,1)-WEEKDAY(DATE($E$2,$K$2,1),2)+1+14))<>$K$2,"",TEXT((DATE($E$2,$K$2,1)-WEEKDAY(DATE($E$2,$K$2,1),2)+1+14),"dd")&CHAR(10)&IF(COUNTIFS(RESERVAS!$C$6:$C$203,"<="&(DATE($E$2,$K$2,1)-WEEKDAY(DATE($E$2,$K$2,1),2)+1+14),RESERVAS!$D$6:$D$203,">"&(DATE($E$2,$K$2,1)-WEEKDAY(DATE($E$2,$K$2,1),2)+1+14),RESERVAS!$I$6:$I$203,"<>Cancelada",RESERVAS!$I$6:$I$203,"<>Consulta")=0,"DISPONÍVEL",IF(COUNTIFS(RESERVAS!$C$6:$C$203,"<="&(DATE($E$2,$K$2,1)-WEEKDAY(DATE($E$2,$K$2,1),2)+1+14),RESERVAS!$D$6:$D$203,">"&(DATE($E$2,$K$2,1)-WEEKDAY(DATE($E$2,$K$2,1),2)+1+14),RESERVAS!$I$6:$I$203,"<>Cancelada",RESERVAS!$I$6:$I$203,"<>Consulta")=1,"ALUGADA","CONFLITO"))&IF(COUNTIFS(RESERVAS!$C$6:$C$203,"<="&(DATE($E$2,$K$2,1)-WEEKDAY(DATE($E$2,$K$2,1),2)+1+14),RESERVAS!$D$6:$D$203,">"&(DATE($E$2,$K$2,1)-WEEKDAY(DATE($E$2,$K$2,1),2)+1+14),RESERVAS!$I$6:$I$203,"<>Cancelada",RESERVAS!$I$6:$I$203,"<>Consulta")=0,"",CHAR(10)&IFERROR(LOOKUP(2,1/((RESERVAS!$C$6:$C$203<=(DATE($E$2,$K$2,1)-WEEKDAY(DATE($E$2,$K$2,1),2)+1+14))*(RESERVAS!$D$6:$D$203>(DATE($E$2,$K$2,1)-WEEKDAY(DATE($E$2,$K$2,1),2)+1+14))*(RESERVAS!$I$6:$I$203<>"Cancelada")*(RESERVAS!$I$6:$I$203<>"Consulta")),RESERVAS!$B$6:$B$203),""))) -> 14 ALUGADA Louis Renan - Férias | B7: =IF(MONTH((DATE($E$2,$K$2,1)-WEEKDAY(DATE($E$2,$K$2,1),2)+1+15))<>$K$2,"",TEXT((DATE($E$2,$K$2,1)-WEEKDAY(DATE($E$2,$K$2,1),2)+1+15),"dd")&CHAR(10)&IF(COUNTIFS(RESERVAS!$C$6:$C$203,"<="&(DATE($E$2,$K$2,1)-WEEKDAY(DATE($E$2,$K$2,1),2)+1+15),RESERVAS!$D$6:$D$203,">"&(DATE($E$2,$K$2,1)-WEEKDAY(DATE($E$2,$K$2,1),2)+1+15),RESERVAS!$I$6:$I$203,"<>Cancelada",RESERVAS!$I$6:$I$203,"<>Consulta")=0,"DISPONÍVEL",IF(COUNTIFS(RESERVAS!$C$6:$C$203,"<="&(DATE($E$2,$K$2,1)-WEEKDAY(DATE($E$2,$K$2,1),2)+1+15),RESERVAS!$D$6:$D$203,">"&(DATE($E$2,$K$2,1)-WEEKDAY(DATE($E$2,$K$2,1),2)+1+15),RESERVAS!$I$6:$I$203,"<>Cancelada",RESERVAS!$I$6:$I$203,"<>Consulta")=1,"ALUGADA","CONFLITO"))&IF(COUNTIFS(RESERVAS!$C$6:$C$203,"<="&(DATE($E$2,$K$2,1)-WEEKDAY(DATE($E$2,$K$2,1),2)+1+15),RESERVAS!$D$6:$D$203,">"&(DATE($E$2,$K$2,1)-WEEKDAY(DATE($E$2,$K$2,1),2)+1+15),RESERVAS!$I$6:$I$203,"<>Cancelada",RESERVAS!$I$6:$I$203,"<>Consulta")=0,"",CHAR(10)&IFERROR(LOOKUP(2,1/((RESERVAS!$C$6:$C$203<=(DATE($E$2,$K$2,1)-WEEKDAY(DATE($E$2,$K$2,1),2)+1+15))*(RESERVAS!$D$6:$D$203>(DATE($E$2,$K$2,1)-WEEKDAY(DATE($E$2,$K$2,1),2)+1+15))*(RESERVAS!$I$6:$I$203<>"Cancelada")*(RESERVAS!$I$6:$I$203<>"Consulta")),RESERVAS!$B$6:$B$203),""))) -> 15 DISPONÍVEL | C7: =IF(MONTH((DATE($E$2,$K$2,1)-WEEKDAY(DATE($E$2,$K$2,1),2)+1+16))<>$K$2,"",TEXT((DATE($E$2,$K$2,1)-WEEKDAY(DATE($E$2,$K$2,1),2)+1+16),"dd")&CHAR(10)&IF(COUNTIFS(RESERVAS!$C$6:$C$203,"<="&(DATE($E$2,$K$2,1)-WEEKDAY(DATE($E$2,$K$2,1),2)+1+16),RESERVAS!$D$6:$D$203,">"&(DATE($E$2,$K$2,1)-WEEKDAY(DATE($E$2,$K$2,1),2)+1+16),RESERVAS!$I$6:$I$203,"<>Cancelada",RESERVAS!$I$6:$I$203,"<>Consulta")=0,"DISPONÍVEL",IF(COUNTIFS(RESERVAS!$C$6:$C$203,"<="&(DATE($E$2,$K$2,1)-WEEKDAY(DATE($E$2,$K$2,1),2)+1+16),RESERVAS!$D$6:$D$203,">"&(DATE($E$2,$K$2,1)-WEEKDAY(DATE($E$2,$K$2,1),2)+1+16),RESERVAS!$I$6:$I$203,"<>Cancelada",RESERVAS!$I$6:$I$203,"<>Consulta")=1,"ALUGADA","CONFLITO"))&IF(COUNTIFS(RESERVAS!$C$6:$C$203,"<="&(DATE($E$2,$K$2,1)-WEEKDAY(DATE($E$2,$K$2,1),2)+1+16),RESERVAS!$D$6:$D$203,">"&(DATE($E$2,$K$2,1)-WEEKDAY(DATE($E$2,$K$2,1),2)+1+16),RESERVAS!$I$6:$I$203,"<>Cancelada",RESERVAS!$I$6:$I$203,"<>Consulta")=0,"",CHAR(10)&IFERROR(LOOKUP(2,1/((RESERVAS!$C$6:$C$203<=(DATE($E$2,$K$2,1)-WEEKDAY(DATE($E$2,$K$2,1),2)+1+16))*(RESERVAS!$D$6:$D$203>(DATE($E$2,$K$2,1)-WEEKDAY(DATE($E$2,$K$2,1),2)+1+16))*(RESERVAS!$I$6:$I$203<>"Cancelada")*(RESERVAS!$I$6:$I$203<>"Consulta")),RESERVAS!$B$6:$B$203),""))) -> 16 DISPONÍVEL | D7: =IF(MONTH((DATE($E$2,$K$2,1)-WEEKDAY(DATE($E$2,$K$2,1),2)+1+17))<>$K$2,"",TEXT((DATE($E$2,$K$2,1)-WEEKDAY(DATE($E$2,$K$2,1),2)+1+17),"dd")&CHAR(10)&IF(COUNTIFS(RESERVAS!$C$6:$C$203,"<="&(DATE($E$2,$K$2,1)-WEEKDAY(DATE($E$2,$K$2,1),2)+1+17),RESERVAS!$D$6:$D$203,">"&(DATE($E$2,$K$2,1)-WEEKDAY(DATE($E$2,$K$2,1),2)+1+17),RESERVAS!$I$6:$I$203,"<>Cancelada",RESERVAS!$I$6:$I$203,"<>Consulta")=0,"DISPONÍVEL",IF(COUNTIFS(RESERVAS!$C$6:$C$203,"<="&(DATE($E$2,$K$2,1)-WEEKDAY(DATE($E$2,$K$2,1),2)+1+17),RESERVAS!$D$6:$D$203,">"&(DATE($E$2,$K$2,1)-WEEKDAY(DATE($E$2,$K$2,1),2)+1+17),RESERVAS!$I$6:$I$203,"<>Cancelada",RESERVAS!$I$6:$I$203,"<>Consulta")=1,"ALUGADA","CONFLITO"))&IF(COUNTIFS(RESERVAS!$C$6:$C$203,"<="&(DATE($E$2,$K$2,1)-WEEKDAY(DATE($E$2,$K$2,1),2)+1+17),RESERVAS!$D$6:$D$203,">"&(DATE($E$2,$K$2,1)-WEEKDAY(DATE($E$2,$K$2,1),2)+1+17),RESERVAS!$I$6:$I$203,"<>Cancelada",RESERVAS!$I$6:$I$203,"<>Consulta")=0,"",CHAR(10)&IFERROR(LOOKUP(2,1/((RESERVAS!$C$6:$C$203<=(DATE($E$2,$K$2,1)-WEEKDAY(DATE($E$2,$K$2,1),2)+1+17))*(RESERVAS!$D$6:$D$203>(DATE($E$2,$K$2,1)-WEEKDAY(DATE($E$2,$K$2,1),2)+1+17))*(RESERVAS!$I$6:$I$203<>"Cancelada")*(RESERVAS!$I$6:$I$203<>"Consulta")),RESERVAS!$B$6:$B$203),""))) -> 17 DISPONÍVEL | E7: =IF(MONTH((DATE($E$2,$K$2,1)-WEEKDAY(DATE($E$2,$K$2,1),2)+1+18))<>$K$2,"",TEXT((DATE($E$2,$K$2,1)-WEEKDAY(DATE($E$2,$K$2,1),2)+1+18),"dd")&CHAR(10)&IF(COUNTIFS(RESERVAS!$C$6:$C$203,"<="&(DATE($E$2,$K$2,1)-WEEKDAY(DATE($E$2,$K$2,1),2)+1+18),RESERVAS!$D$6:$D$203,">"&(DATE($E$2,$K$2,1)-WEEKDAY(DATE($E$2,$K$2,1),2)+1+18),RESERVAS!$I$6:$I$203,"<>Cancelada",RESERVAS!$I$6:$I$203,"<>Consulta")=0,"DISPONÍVEL",IF(COUNTIFS(RESERVAS!$C$6:$C$203,"<="&(DATE($E$2,$K$2,1)-WEEKDAY(DATE($E$2,$K$2,1),2)+1+18),RESERVAS!$D$6:$D$203,">"&(DATE($E$2,$K$2,1)-WEEKDAY(DATE($E$2,$K$2,1),2)+1+18),RESERVAS!$I$6:$I$203,"<>Cancelada",RESERVAS!$I$6:$I$203,"<>Consulta")=1,"ALUGADA","CONFLITO"))&IF(COUNTIFS(RESERVAS!$C$6:$C$203,"<="&(DATE($E$2,$K$2,1)-WEEKDAY(DATE($E$2,$K$2,1),2)+1+18),RESERVAS!$D$6:$D$203,">"&(DATE($E$2,$K$2,1)-WEEKDAY(DATE($E$2,$K$2,1),2)+1+18),RESERVAS!$I$6:$I$203,"<>Cancelada",RESERVAS!$I$6:$I$203,"<>Consulta")=0,"",CHAR(10)&IFERROR(LOOKUP(2,1/((RESERVAS!$C$6:$C$203<=(DATE($E$2,$K$2,1)-WEEKDAY(DATE($E$2,$K$2,1),2)+1+18))*(RESERVAS!$D$6:$D$203>(DATE($E$2,$K$2,1)-WEEKDAY(DATE($E$2,$K$2,1),2)+1+18))*(RESERVAS!$I$6:$I$203<>"Cancelada")*(RESERVAS!$I$6:$I$203<>"Consulta")),RESERVAS!$B$6:$B$203),""))) -> 18 DISPONÍVEL | F7: =IF(MONTH((DATE($E$2,$K$2,1)-WEEKDAY(DATE($E$2,$K$2,1),2)+1+19))<>$K$2,"",TEXT((DATE($E$2,$K$2,1)-WEEKDAY(DATE($E$2,$K$2,1),2)+1+19),"dd")&CHAR(10)&IF(COUNTIFS(RESERVAS!$C$6:$C$203,"<="&(DATE($E$2,$K$2,1)-WEEKDAY(DATE($E$2,$K$2,1),2)+1+19),RESERVAS!$D$6:$D$203,">"&(DATE($E$2,$K$2,1)-WEEKDAY(DATE($E$2,$K$2,1),2)+1+19),RESERVAS!$I$6:$I$203,"<>Cancelada",RESERVAS!$I$6:$I$203,"<>Consulta")=0,"DISPONÍVEL",IF(COUNTIFS(RESERVAS!$C$6:$C$203,"<="&(DATE($E$2,$K$2,1)-WEEKDAY(DATE($E$2,$K$2,1),2)+1+19),RESERVAS!$D$6:$D$203,">"&(DATE($E$2,$K$2,1)-WEEKDAY(DATE($E$2,$K$2,1),2)+1+19),RESERVAS!$I$6:$I$203,"<>Cancelada",RESERVAS!$I$6:$I$203,"<>Consulta")=1,"ALUGADA","CONFLITO"))&IF(COUNTIFS(RESERVAS!$C$6:$C$203,"<="&(DATE($E$2,$K$2,1)-WEEKDAY(DATE($E$2,$K$2,1),2)+1+19),RESERVAS!$D$6:$D$203,">"&(DATE($E$2,$K$2,1)-WEEKDAY(DATE($E$2,$K$2,1),2)+1+19),RESERVAS!$I$6:$I$203,"<>Cancelada",RESERVAS!$I$6:$I$203,"<>Consulta")=0,"",CHAR(10)&IFERROR(LOOKUP(2,1/((RESERVAS!$C$6:$C$203<=(DATE($E$2,$K$2,1)-WEEKDAY(DATE($E$2,$K$2,1),2)+1+19))*(RESERVAS!$D$6:$D$203>(DATE($E$2,$K$2,1)-WEEKDAY(DATE($E$2,$K$2,1),2)+1+19))*(RESERVAS!$I$6:$I$203<>"Cancelada")*(RESERVAS!$I$6:$I$203<>"Consulta")),RESERVAS!$B$6:$B$203),""))) -> 19 DISPONÍVEL | G7: =IF(MONTH((DATE($E$2,$K$2,1)-WEEKDAY(DATE($E$2,$K$2,1),2)+1+20))<>$K$2,"",TEXT((DATE($E$2,$K$2,1)-WEEKDAY(DATE($E$2,$K$2,1),2)+1+20),"dd")&CHAR(10)&IF(COUNTIFS(RESERVAS!$C$6:$C$203,"<="&(DATE($E$2,$K$2,1)-WEEKDAY(DATE($E$2,$K$2,1),2)+1+20),RESERVAS!$D$6:$D$203,">"&(DATE($E$2,$K$2,1)-WEEKDAY(DATE($E$2,$K$2,1),2)+1+20),RESERVAS!$I$6:$I$203,"<>Cancelada",RESERVAS!$I$6:$I$203,"<>Consulta")=0,"DISPONÍVEL",IF(COUNTIFS(RESERVAS!$C$6:$C$203,"<="&(DATE($E$2,$K$2,1)-WEEKDAY(DATE($E$2,$K$2,1),2)+1+20),RESERVAS!$D$6:$D$203,">"&(DATE($E$2,$K$2,1)-WEEKDAY(DATE($E$2,$K$2,1),2)+1+20),RESERVAS!$I$6:$I$203,"<>Cancelada",RESERVAS!$I$6:$I$203,"<>Consulta")=1,"ALUGADA","CONFLITO"))&IF(COUNTIFS(RESERVAS!$C$6:$C$203,"<="&(DATE($E$2,$K$2,1)-WEEKDAY(DATE($E$2,$K$2,1),2)+1+20),RESERVAS!$D$6:$D$203,">"&(DATE($E$2,$K$2,1)-WEEKDAY(DATE($E$2,$K$2,1),2)+1+20),RESERVAS!$I$6:$I$203,"<>Cancelada",RESERVAS!$I$6:$I$203,"<>Consulta")=0,"",CHAR(10)&IFERROR(LOOKUP(2,1/((RESERVAS!$C$6:$C$203<=(DATE($E$2,$K$2,1)-WEEKDAY(DATE($E$2,$K$2,1),2)+1+20))*(RESERVAS!$D$6:$D$203>(DATE($E$2,$K$2,1)-WEEKDAY(DATE($E$2,$K$2,1),2)+1+20))*(RESERVAS!$I$6:$I$203<>"Cancelada")*(RESERVAS!$I$6:$I$203<>"Consulta")),RESERVAS!$B$6:$B$203),""))) -> 20 DISPONÍVEL | I7: Despesas gerais (R$) | J7: =SUMIFS('DESPESAS CASA'!$D$6:$D$305,'DESPESAS CASA'!$A$6:$A$305,">="&DATE($E$2,$K$2,1),'DESPESAS CASA'!$A$6:$A$305,"<"&DATE($E$2,$K$2+1,1),'DESPESAS CASA'!$E$6:$E$305,"") -> 0
A8: =IF(MONTH((DATE($E$2,$K$2,1)-WEEKDAY(DATE($E$2,$K$2,1),2)+1+21))<>$K$2,"",TEXT((DATE($E$2,$K$2,1)-WEEKDAY(DATE($E$2,$K$2,1),2)+1+21),"dd")&CHAR(10)&IF(COUNTIFS(RESERVAS!$C$6:$C$203,"<="&(DATE($E$2,$K$2,1)-WEEKDAY(DATE($E$2,$K$2,1),2)+1+21),RESERVAS!$D$6:$D$203,">"&(DATE($E$2,$K$2,1)-WEEKDAY(DATE($E$2,$K$2,1),2)+1+21),RESERVAS!$I$6:$I$203,"<>Cancelada",RESERVAS!$I$6:$I$203,"<>Consulta")=0,"DISPONÍVEL",IF(COUNTIFS(RESERVAS!$C$6:$C$203,"<="&(DATE($E$2,$K$2,1)-WEEKDAY(DATE($E$2,$K$2,1),2)+1+21),RESERVAS!$D$6:$D$203,">"&(DATE($E$2,$K$2,1)-WEEKDAY(DATE($E$2,$K$2,1),2)+1+21),RESERVAS!$I$6:$I$203,"<>Cancelada",RESERVAS!$I$6:$I$203,"<>Consulta")=1,"ALUGADA","CONFLITO"))&IF(COUNTIFS(RESERVAS!$C$6:$C$203,"<="&(DATE($E$2,$K$2,1)-WEEKDAY(DATE($E$2,$K$2,1),2)+1+21),RESERVAS!$D$6:$D$203,">"&(DATE($E$2,$K$2,1)-WEEKDAY(DATE($E$2,$K$2,1),2)+1+21),RESERVAS!$I$6:$I$203,"<>Cancelada",RESERVAS!$I$6:$I$203,"<>Consulta")=0,"",CHAR(10)&IFERROR(LOOKUP(2,1/((RESERVAS!$C$6:$C$203<=(DATE($E$2,$K$2,1)-WEEKDAY(DATE($E$2,$K$2,1),2)+1+21))*(RESERVAS!$D$6:$D$203>(DATE($E$2,$K$2,1)-WEEKDAY(DATE($E$2,$K$2,1),2)+1+21))*(RESERVAS!$I$6:$I$203<>"Cancelada")*(RESERVAS!$I$6:$I$203<>"Consulta")),RESERVAS!$B$6:$B$203),""))) -> 21 DISPONÍVEL | B8: =IF(MONTH((DATE($E$2,$K$2,1)-WEEKDAY(DATE($E$2,$K$2,1),2)+1+22))<>$K$2,"",TEXT((DATE($E$2,$K$2,1)-WEEKDAY(DATE($E$2,$K$2,1),2)+1+22),"dd")&CHAR(10)&IF(COUNTIFS(RESERVAS!$C$6:$C$203,"<="&(DATE($E$2,$K$2,1)-WEEKDAY(DATE($E$2,$K$2,1),2)+1+22),RESERVAS!$D$6:$D$203,">"&(DATE($E$2,$K$2,1)-WEEKDAY(DATE($E$2,$K$2,1),2)+1+22),RESERVAS!$I$6:$I$203,"<>Cancelada",RESERVAS!$I$6:$I$203,"<>Consulta")=0,"DISPONÍVEL",IF(COUNTIFS(RESERVAS!$C$6:$C$203,"<="&(DATE($E$2,$K$2,1)-WEEKDAY(DATE($E$2,$K$2,1),2)+1+22),RESERVAS!$D$6:$D$203,">"&(DATE($E$2,$K$2,1)-WEEKDAY(DATE($E$2,$K$2,1),2)+1+22),RESERVAS!$I$6:$I$203,"<>Cancelada",RESERVAS!$I$6:$I$203,"<>Consulta")=1,"ALUGADA","CONFLITO"))&IF(COUNTIFS(RESERVAS!$C$6:$C$203,"<="&(DATE($E$2,$K$2,1)-WEEKDAY(DATE($E$2,$K$2,1),2)+1+22),RESERVAS!$D$6:$D$203,">"&(DATE($E$2,$K$2,1)-WEEKDAY(DATE($E$2,$K$2,1),2)+1+22),RESERVAS!$I$6:$I$203,"<>Cancelada",RESERVAS!$I$6:$I$203,"<>Consulta")=0,"",CHAR(10)&IFERROR(LOOKUP(2,1/((RESERVAS!$C$6:$C$203<=(DATE($E$2,$K$2,1)-WEEKDAY(DATE($E$2,$K$2,1),2)+1+22))*(RESERVAS!$D$6:$D$203>(DATE($E$2,$K$2,1)-WEEKDAY(DATE($E$2,$K$2,1),2)+1+22))*(RESERVAS!$I$6:$I$203<>"Cancelada")*(RESERVAS!$I$6:$I$203<>"Consulta")),RESERVAS!$B$6:$B$203),""))) -> 22 DISPONÍVEL | C8: =IF(MONTH((DATE($E$2,$K$2,1)-WEEKDAY(DATE($E$2,$K$2,1),2)+1+23))<>$K$2,"",TEXT((DATE($E$2,$K$2,1)-WEEKDAY(DATE($E$2,$K$2,1),2)+1+23),"dd")&CHAR(10)&IF(COUNTIFS(RESERVAS!$C$6:$C$203,"<="&(DATE($E$2,$K$2,1)-WEEKDAY(DATE($E$2,$K$2,1),2)+1+23),RESERVAS!$D$6:$D$203,">"&(DATE($E$2,$K$2,1)-WEEKDAY(DATE($E$2,$K$2,1),2)+1+23),RESERVAS!$I$6:$I$203,"<>Cancelada",RESERVAS!$I$6:$I$203,"<>Consulta")=0,"DISPONÍVEL",IF(COUNTIFS(RESERVAS!$C$6:$C$203,"<="&(DATE($E$2,$K$2,1)-WEEKDAY(DATE($E$2,$K$2,1),2)+1+23),RESERVAS!$D$6:$D$203,">"&(DATE($E$2,$K$2,1)-WEEKDAY(DATE($E$2,$K$2,1),2)+1+23),RESERVAS!$I$6:$I$203,"<>Cancelada",RESERVAS!$I$6:$I$203,"<>Consulta")=1,"ALUGADA","CONFLITO"))&IF(COUNTIFS(RESERVAS!$C$6:$C$203,"<="&(DATE($E$2,$K$2,1)-WEEKDAY(DATE($E$2,$K$2,1),2)+1+23),RESERVAS!$D$6:$D$203,">"&(DATE($E$2,$K$2,1)-WEEKDAY(DATE($E$2,$K$2,1),2)+1+23),RESERVAS!$I$6:$I$203,"<>Cancelada",RESERVAS!$I$6:$I$203,"<>Consulta")=0,"",CHAR(10)&IFERROR(LOOKUP(2,1/((RESERVAS!$C$6:$C$203<=(DATE($E$2,$K$2,1)-WEEKDAY(DATE($E$2,$K$2,1),2)+1+23))*(RESERVAS!$D$6:$D$203>(DATE($E$2,$K$2,1)-WEEKDAY(DATE($E$2,$K$2,1),2)+1+23))*(RESERVAS!$I$6:$I$203<>"Cancelada")*(RESERVAS!$I$6:$I$203<>"Consulta")),RESERVAS!$B$6:$B$203),""))) -> 23 DISPONÍVEL | D8: =IF(MONTH((DATE($E$2,$K$2,1)-WEEKDAY(DATE($E$2,$K$2,1),2)+1+24))<>$K$2,"",TEXT((DATE($E$2,$K$2,1)-WEEKDAY(DATE($E$2,$K$2,1),2)+1+24),"dd")&CHAR(10)&IF(COUNTIFS(RESERVAS!$C$6:$C$203,"<="&(DATE($E$2,$K$2,1)-WEEKDAY(DATE($E$2,$K$2,1),2)+1+24),RESERVAS!$D$6:$D$203,">"&(DATE($E$2,$K$2,1)-WEEKDAY(DATE($E$2,$K$2,1),2)+1+24),RESERVAS!$I$6:$I$203,"<>Cancelada",RESERVAS!$I$6:$I$203,"<>Consulta")=0,"DISPONÍVEL",IF(COUNTIFS(RESERVAS!$C$6:$C$203,"<="&(DATE($E$2,$K$2,1)-WEEKDAY(DATE($E$2,$K$2,1),2)+1+24),RESERVAS!$D$6:$D$203,">"&(DATE($E$2,$K$2,1)-WEEKDAY(DATE($E$2,$K$2,1),2)+1+24),RESERVAS!$I$6:$I$203,"<>Cancelada",RESERVAS!$I$6:$I$203,"<>Consulta")=1,"ALUGADA","CONFLITO"))&IF(COUNTIFS(RESERVAS!$C$6:$C$203,"<="&(DATE($E$2,$K$2,1)-WEEKDAY(DATE($E$2,$K$2,1),2)+1+24),RESERVAS!$D$6:$D$203,">"&(DATE($E$2,$K$2,1)-WEEKDAY(DATE($E$2,$K$2,1),2)+1+24),RESERVAS!$I$6:$I$203,"<>Cancelada",RESERVAS!$I$6:$I$203,"<>Consulta")=0,"",CHAR(10)&IFERROR(LOOKUP(2,1/((RESERVAS!$C$6:$C$203<=(DATE($E$2,$K$2,1)-WEEKDAY(DATE($E$2,$K$2,1),2)+1+24))*(RESERVAS!$D$6:$D$203>(DATE($E$2,$K$2,1)-WEEKDAY(DATE($E$2,$K$2,1),2)+1+24))*(RESERVAS!$I$6:$I$203<>"Cancelada")*(RESERVAS!$I$6:$I$203<>"Consulta")),RESERVAS!$B$6:$B$203),""))) -> 24 DISPONÍVEL | E8: =IF(MONTH((DATE($E$2,$K$2,1)-WEEKDAY(DATE($E$2,$K$2,1),2)+1+25))<>$K$2,"",TEXT((DATE($E$2,$K$2,1)-WEEKDAY(DATE($E$2,$K$2,1),2)+1+25),"dd")&CHAR(10)&IF(COUNTIFS(RESERVAS!$C$6:$C$203,"<="&(DATE($E$2,$K$2,1)-WEEKDAY(DATE($E$2,$K$2,1),2)+1+25),RESERVAS!$D$6:$D$203,">"&(DATE($E$2,$K$2,1)-WEEKDAY(DATE($E$2,$K$2,1),2)+1+25),RESERVAS!$I$6:$I$203,"<>Cancelada",RESERVAS!$I$6:$I$203,"<>Consulta")=0,"DISPONÍVEL",IF(COUNTIFS(RESERVAS!$C$6:$C$203,"<="&(DATE($E$2,$K$2,1)-WEEKDAY(DATE($E$2,$K$2,1),2)+1+25),RESERVAS!$D$6:$D$203,">"&(DATE($E$2,$K$2,1)-WEEKDAY(DATE($E$2,$K$2,1),2)+1+25),RESERVAS!$I$6:$I$203,"<>Cancelada",RESERVAS!$I$6:$I$203,"<>Consulta")=1,"ALUGADA","CONFLITO"))&IF(COUNTIFS(RESERVAS!$C$6:$C$203,"<="&(DATE($E$2,$K$2,1)-WEEKDAY(DATE($E$2,$K$2,1),2)+1+25),RESERVAS!$D$6:$D$203,">"&(DATE($E$2,$K$2,1)-WEEKDAY(DATE($E$2,$K$2,1),2)+1+25),RESERVAS!$I$6:$I$203,"<>Cancelada",RESERVAS!$I$6:$I$203,"<>Consulta")=0,"",CHAR(10)&IFERROR(LOOKUP(2,1/((RESERVAS!$C$6:$C$203<=(DATE($E$2,$K$2,1)-WEEKDAY(DATE($E$2,$K$2,1),2)+1+25))*(RESERVAS!$D$6:$D$203>(DATE($E$2,$K$2,1)-WEEKDAY(DATE($E$2,$K$2,1),2)+1+25))*(RESERVAS!$I$6:$I$203<>"Cancelada")*(RESERVAS!$I$6:$I$203<>"Consulta")),RESERVAS!$B$6:$B$203),""))) -> 25 DISPONÍVEL | F8: =IF(MONTH((DATE($E$2,$K$2,1)-WEEKDAY(DATE($E$2,$K$2,1),2)+1+26))<>$K$2,"",TEXT((DATE($E$2,$K$2,1)-WEEKDAY(DATE($E$2,$K$2,1),2)+1+26),"dd")&CHAR(10)&IF(COUNTIFS(RESERVAS!$C$6:$C$203,"<="&(DATE($E$2,$K$2,1)-WEEKDAY(DATE($E$2,$K$2,1),2)+1+26),RESERVAS!$D$6:$D$203,">"&(DATE($E$2,$K$2,1)-WEEKDAY(DATE($E$2,$K$2,1),2)+1+26),RESERVAS!$I$6:$I$203,"<>Cancelada",RESERVAS!$I$6:$I$203,"<>Consulta")=0,"DISPONÍVEL",IF(COUNTIFS(RESERVAS!$C$6:$C$203,"<="&(DATE($E$2,$K$2,1)-WEEKDAY(DATE($E$2,$K$2,1),2)+1+26),RESERVAS!$D$6:$D$203,">"&(DATE($E$2,$K$2,1)-WEEKDAY(DATE($E$2,$K$2,1),2)+1+26),RESERVAS!$I$6:$I$203,"<>Cancelada",RESERVAS!$I$6:$I$203,"<>Consulta")=1,"ALUGADA","CONFLITO"))&IF(COUNTIFS(RESERVAS!$C$6:$C$203,"<="&(DATE($E$2,$K$2,1)-WEEKDAY(DATE($E$2,$K$2,1),2)+1+26),RESERVAS!$D$6:$D$203,">"&(DATE($E$2,$K$2,1)-WEEKDAY(DATE($E$2,$K$2,1),2)+1+26),RESERVAS!$I$6:$I$203,"<>Cancelada",RESERVAS!$I$6:$I$203,"<>Consulta")=0,"",CHAR(10)&IFERROR(LOOKUP(2,1/((RESERVAS!$C$6:$C$203<=(DATE($E$2,$K$2,1)-WEEKDAY(DATE($E$2,$K$2,1),2)+1+26))*(RESERVAS!$D$6:$D$203>(DATE($E$2,$K$2,1)-WEEKDAY(DATE($E$2,$K$2,1),2)+1+26))*(RESERVAS!$I$6:$I$203<>"Cancelada")*(RESERVAS!$I$6:$I$203<>"Consulta")),RESERVAS!$B$6:$B$203),""))) -> 26 DISPONÍVEL | G8: =IF(MONTH((DATE($E$2,$K$2,1)-WEEKDAY(DATE($E$2,$K$2,1),2)+1+27))<>$K$2,"",TEXT((DATE($E$2,$K$2,1)-WEEKDAY(DATE($E$2,$K$2,1),2)+1+27),"dd")&CHAR(10)&IF(COUNTIFS(RESERVAS!$C$6:$C$203,"<="&(DATE($E$2,$K$2,1)-WEEKDAY(DATE($E$2,$K$2,1),2)+1+27),RESERVAS!$D$6:$D$203,">"&(DATE($E$2,$K$2,1)-WEEKDAY(DATE($E$2,$K$2,1),2)+1+27),RESERVAS!$I$6:$I$203,"<>Cancelada",RESERVAS!$I$6:$I$203,"<>Consulta")=0,"DISPONÍVEL",IF(COUNTIFS(RESERVAS!$C$6:$C$203,"<="&(DATE($E$2,$K$2,1)-WEEKDAY(DATE($E$2,$K$2,1),2)+1+27),RESERVAS!$D$6:$D$203,">"&(DATE($E$2,$K$2,1)-WEEKDAY(DATE($E$2,$K$2,1),2)+1+27),RESERVAS!$I$6:$I$203,"<>Cancelada",RESERVAS!$I$6:$I$203,"<>Consulta")=1,"ALUGADA","CONFLITO"))&IF(COUNTIFS(RESERVAS!$C$6:$C$203,"<="&(DATE($E$2,$K$2,1)-WEEKDAY(DATE($E$2,$K$2,1),2)+1+27),RESERVAS!$D$6:$D$203,">"&(DATE($E$2,$K$2,1)-WEEKDAY(DATE($E$2,$K$2,1),2)+1+27),RESERVAS!$I$6:$I$203,"<>Cancelada",RESERVAS!$I$6:$I$203,"<>Consulta")=0,"",CHAR(10)&IFERROR(LOOKUP(2,1/((RESERVAS!$C$6:$C$203<=(DATE($E$2,$K$2,1)-WEEKDAY(DATE($E$2,$K$2,1),2)+1+27))*(RESERVAS!$D$6:$D$203>(DATE($E$2,$K$2,1)-WEEKDAY(DATE($E$2,$K$2,1),2)+1+27))*(RESERVAS!$I$6:$I$203<>"Cancelada")*(RESERVAS!$I$6:$I$203<>"Consulta")),RESERVAS!$B$6:$B$203),""))) -> 27 DISPONÍVEL | I8: Lucro final (R$) | J8: =J5-J6-J7 -> 2767.95
